Workbook

Sheet 1
A1: Pack | B1: Flavour | C1: MRP | D1: Stock PC | E1: Recived pc | F1: Recived invoice | G1: Total PC | H1: Invoce cost | I1: Amount | J1: sale price | K1: Amount | L1: SALE Pc | M1: SALE Amount
A2: 150 ml Tetra | B2: Mazza | C2: 9 | D2: 167 | F2: =E2*H2 -> 0 | G2: =D2+E2 -> 167 | H2: 308.13 | I2: =H2*D2 -> 51457.71 | J2: 326 | K2: =J2*D2 -> 54442 | L2: =G2-'2'!D2 -> 0 | M2: =L2*J2 -> 0
A3: 150 ml Tetra | B3: MM Apple | C3: 9 | D3: 1 | E3: 70 | F3: =E3*H3 -> 21573.3 | G3: =D3+E3 -> 71 | H3: 308.19 | I3: =H3*D3 -> 308.19 | J3: 326 | K3: =J3*D3 -> 326 | L3: =G3-'2'!D3 -> 0 | M3: =L3*J3 -> 0
A4: 150 ml Tetra | B4: MM LMN Fresh | C4: 9 | F4: =E4*H4 -> 0 | G4: =D4+E4 -> 0 | H4: 308.19 | I4: =H4*D4 -> 0 | J4: 326 | K4: =J4*D4 -> 0 | L4: =G4-'2'!D4 -> 0 | M4: =L4*J4 -> 0
A5: 200 ml RGB | B5: Thums up | C5: 10 | D5: 99 | F5: =E5*H5 -> 0 | G5: =D5+E5 -> 99 | H5: 174.77 | I5: =H5*D5 -> 17302.23 | J5: 192 | K5: =J5*D5 -> 19008 | L5: =G5-'2'!D5 -> 0 | M5: =L5*J5 -> 0
A6: 200 ml RGB | B6: Sprite | C6: 10 | D6: 151 | F6: =E6*H6 -> 0 | G6: =D6+E6 -> 151 | H6: 174.77 | I6: =H6*D6 -> 26390.27 | J6: 192 | K6: =J6*D6 -> 28992 | L6: =G6-'2'!D6 -> 0 | M6: =L6*J6 -> 0
A7: 200 ml RGB | B7: Limca | C7: 10 | D7: 64 | F7: =E7*H7 -> 0 | G7: =D7+E7 -> 64 | H7: 174.77 | I7: =H7*D7 -> 11185.28 | J7: 192 | K7: =J7*D7 -> 12288 | L7: =G7-'2'!D7 -> 0 | M7: =L7*J7 -> 0
A8: 200 ml RGB | B8: Fanta | C8: 10 | D8: 34 | F8: =E8*H8 -> 0 | G8: =D8+E8 -> 34 | H8: 174.77 | I8: =H8*D8 -> 5942.18 | J8: 192 | K8: =J8*D8 -> 6528 | L8: =G8-'2'!D8 -> 0 | M8: =L8*J8 -> 0
A9: 200 ml RGB | B9: Coke | C9: 10 | D9: 216 | F9: =E9*H9 -> 0 | G9: =D9+E9 -> 216 | H9: 174.77 | I9: =H9*D9 -> 37750.32 | J9: 192 | K9: =J9*D9 -> 41472 | L9: =G9-'2'!D9 -> 0 | M9: =L9*J9 -> 0
A10: 200 ml RGB | B10: Mazza | C10: 14 | F10: =E10*H10 -> 0 | G10: =D10+E10 -> 0 | H10: 259.54 | I10: =H10*D10 -> 0 | J10: 282 | K10: =J10*D10 -> 0 | L10: =G10-'2'!D10 -> 0 | M10: =L10*J10 -> 0
A11: 250 ml PET | B11: Thums up Charge | C11: 20 | D11: 5 | E11: 39 | F11: =E11*H11 -> 18361.2 | G11: =D11+E11 -> 44 | H11: 470.8 | I11: =H11*D11 -> 2354 | J11: 505 | K11: =J11*D11 -> 2525 | L11: =G11-'2'!D11 -> 1 | M11: =L11*J11 -> 505
A12: 250 ml PET | B12: Thums up | C12: 20 | D12: 94 | E12: 390 | F12: =E12*H12 -> 185550.3 | G12: =D12+E12 -> 484 | H12: 475.77 | I12: =H12*D12 -> 44722.38 | J12: 505 | K12: =J12*D12 -> 47470 | L12: =G12-'2'!D12 -> 0 | M12: =L12*J12 -> 0
A13: 250 ml PET | B13: Sprite | C13: 20 | D13: 138 | E13: 260 | F13: =E13*H13 -> 123700.2 | G13: =D13+E13 -> 398 | H13: 475.77 | I13: =H13*D13 -> 65656.26 | J13: 505 | K13: =J13*D13 -> 69690 | L13: =G13-'2'!D13 -> 0 | M13: =L13*J13 -> 0
A14: 250 ml PET | B14: Limca | C14: 20 | D14: 5 | E14: 65 | F14: =E14*H14 -> 30602 | G14: =D14+E14 -> 70 | H14: 470.8 | I14: =H14*D14 -> 2354 | J14: 505 | K14: =J14*D14 -> 2525 | L14: =G14-'2'!D14 -> 0 | M14: =L14*J14 -> 0
A15: 250 ml PET | B15: Fanta | C15: 20 | E15: 65 | F15: =E15*H15 -> 30602 | G15: =D15+E15 -> 65 | H15: 470.8 | I15: =H15*D15 -> 0 | J15: 505 | K15: =J15*D15 -> 0 | L15: =G15-'2'!D15 -> 0 | M15: =L15*J15 -> 0
A16: 250 ml PET | B16: Coke | C16: 20 | D16: 2 | F16: =E16*H16 -> 0 | G16: =D16+E16 -> 2 | H16: 470.8 | I16: =H16*D16 -> 941.6 | J16: 505 | K16: =J16*D16 -> 1010 | L16: =G16-'2'!D16 -> 0 | M16: =L16*J16 -> 0
A17: 250 ml PET | B17: Kinley Soda | C17: 11 | D17: 102 | F17: =E17*H17 -> 0 | G17: =D17+E17 -> 102 | H17: 235.59 | I17: =H17*D17 -> 24030.18 | J17: 250 | K17: =J17*D17 -> 25500 | L17: =G17-'2'!D17 -> 0 | M17: =L17*J17 -> 0
A18: 250 ml PET | B18: RimZim Fiz | C18: 20 | F18: =E18*H18 -> 0 | G18: =D18+E18 -> 0 | H18: 470.8 | I18: =H18*D18 -> 0 | J18: 500 | K18: =J18*D18 -> 0 | L18: =G18-'2'!D18 -> 0 | M18: =L18*J18 -> 0
A19: 250 ml PET | B19: Zero Thums up | C19: 10 | F19: =E19*H19 -> 0 | G19: =D19+E19 -> 0 | H19: 204 | I19: =H19*D19 -> 0 | J19: 230 | K19: =J19*D19 -> 0 | L19: =G19-'2'!D19 -> 0 | M19: =L19*J19 -> 0
A20: 250 ml PET | B20: Zero Sprite | C20: 10 | F20: =E20*H20 -> 0 | G20: =D20+E20 -> 0 | H20: 204 | I20: =H20*D20 -> 0 | J20: 230 | K20: =J20*D20 -> 0 | L20: =G20-'2'!D20 -> 0 | M20: =L20*J20 -> 0
A21: 250 ml PET | B21: Zero Coke | C21: 10 | D21: 32 | F21: =E21*H21 -> 0 | G21: =D21+E21 -> 32 | H21: 204 | I21: =H21*D21 -> 6528 | J21: 230 | K21: =J21*D21 -> 7360 | L21: =G21-'2'!D21 -> 0 | M21: =L21*J21 -> 0
A22: 250 ml PET | B22: Mazza | C22: 19 | D22: 7 | E22: 108 | F22: =E22*H22 -> 51241.68 | G22: =D22+E22 -> 115 | H22: 474.46 | I22: =H22*D22 -> 3321.22 | J22: 505 | K22: =J22*D22 -> 3535 | L22: =G22-'2'!D22 -> 0 | M22: =L22*J22 -> 0
A23: 250 ml PET | B23: MM Pulpy orange | C23: 24 | D23: 103 | F23: =E23*H23 -> 0 | G23: =D23+E23 -> 103 | H23: 593.92 | I23: =H23*D23 -> 61173.76 | J23: 630 | K23: =J23*D23 -> 64890 | L23: =G23-'2'!D23 -> 0 | M23: =L23*J23 -> 0
A24: 300 ml RGB | B24: Thums up | C24: 25 | D24: 9 | F24: =E24*H24 -> 0 | G24: =D24+E24 -> 9 | H24: 453.3 | I24: =H24*D24 -> 4079.7 | J24: 493 | K24: =J24*D24 -> 4437 | L24: =G24-'2'!D24 -> 0 | M24: =L24*J24 -> 0
A25: 300 ml RGB | B25: Sprite | C25: 25 | F25: =E25*H25 -> 0 | G25: =D25+E25 -> 0 | H25: 453.3 | I25: =H25*D25 -> 0 | J25: 493 | K25: =J25*D25 -> 0 | L25: =G25-'2'!D25 -> 0 | M25: =L25*J25 -> 0
A26: 300 ml RGB | B26: Fanta | C26: 25 | F26: =E26*H26 -> 0 | G26: =D26+E26 -> 0 | H26: 453.3 | I26: =H26*D26 -> 0 | J26: 493 | K26: =J26*D26 -> 0 | L26: =G26-'2'!D26 -> 0 | M26: =L26*J26 -> 0
A27: 300 ml RGB | B27: Coke | C27: 25 | F27: =E27*H27 -> 0 | G27: =D27+E27 -> 0 | H27: 453.3 | I27: =H27*D27 -> 0 | J27: 493 | K27: =J27*D27 -> 0 | L27: =G27-'2'!D27 -> 0 | M27: =L27*J27 -> 0
A28: 300 ml CAN | B28: Thums up | C28: 40 | F28: =E28*H28 -> 0 | G28: =D28+E28 -> 0 | H28: 821.36 | I28: =H28*D28 -> 0 | J28: 878 | K28: =J28*D28 -> 0 | L28: =G28-'2'!D28 -> 0 | M28: =L28*J28 -> 0
A29: 300 ml CAN | B29: Sprite | C29: 40 | F29: =E29*H29 -> 0 | G29: =D29+E29 -> 0 | H29: 821.36 | I29: =H29*D29 -> 0 | J29: 878 | K29: =J29*D29 -> 0 | L29: =G29-'2'!D29 -> 0 | M29: =L29*J29 -> 0
A30: 300 ml CAN | B30: Limca | C30: 40 | F30: =E30*H30 -> 0 | G30: =D30+E30 -> 0 | H30: 817.58 | I30: =H30*D30 -> 0 | J30: 878 | K30: =J30*D30 -> 0 | L30: =G30-'2'!D30 -> 0 | M30: =L30*J30 -> 0
A31: 300 ml CAN | B31: Fanta | C31: 40 | F31: =E31*H31 -> 0 | G31: =D31+E31 -> 0 | H31: 817.58 | I31: =H31*D31 -> 0 | J31: 878 | K31: =J31*D31 -> 0 | L31: =G31-'2'!D31 -> 0 | M31: =L31*J31 -> 0
A32: 300 ml CAN | B32: Coke | C32: 40 | F32: =E32*H32 -> 0 | G32: =D32+E32 -> 0 | H32: 817.58 | I32: =H32*D32 -> 0 | J32: 878 | K32: =J32*D32 -> 0 | L32: =G32-'2'!D32 -> 0 | M32: =L32*J32 -> 0
A33: 300 ml CAN | B33: D'Coke | C33: 40 | F33: =E33*H33 -> 0 | G33: =D33+E33 -> 0 | H33: 817.58 | I33: =H33*D33 -> 0 | J33: 878 | K33: =J33*D33 -> 0 | L33: =G33-'2'!D33 -> 0 | M33: =L33*J33 -> 0
A34: 300 ml CAN | B34: Predator | C34: 60 | D34: 1 | F34: =E34*H34 -> 0 | G34: =D34+E34 -> 1 | H34: 1042.65 | I34: =H34*D34 -> 1042.65 | J34: 1110 | K34: =J34*D34 -> 1110 | L34: =G34-'2'!D34 -> 0 | M34: =L34*J34 -> 0
A35: 300 ml | B35: Kinley Water | C35: 7 | D35: 16 | F35: =E35*H35 -> 0 | G35: =D35+E35 -> 16 | H35: 126.24 | I35: =H35*D35 -> 2019.84 | J35: 140 | K35: =J35*D35 -> 2240 | L35: =G35-'2'!D35 -> 0 | M35: =L35*J35 -> 0
A36: 350 ml CAN | B36: Monster | C36: 125 | D36: 3 | F36: =E36*H36 -> 0 | G36: =D36+E36 -> 3 | H36: 2050.54 | I36: =H36*D36 -> 6151.62 | J36: 2175 | K36: =J36*D36 -> 6525 | L36: =G36-'2'!D36 -> 0 | M36: =L36*J36 -> 0
A37: 400 ml csd | B37: Thums up | C37: 20 | D37: 3 | F37: =E37*H37 -> 0 | G37: =D37+E37 -> 3 | H37: 399.19 | I37: =H37*D37 -> 1197.57 | J37: 420 | K37: =J37*D37 -> 1260 | L37: =G37-'2'!D37 -> 0 | M37: =L37*J37 -> 0
A38: 400 ml csd | B38: Sprite | C38: 20 | F38: =E38*H38 -> 0 | G38: =D38+E38 -> 0 | H38: 399.19 | I38: =H38*D38 -> 0 | J38: 420 | K38: =J38*D38 -> 0 | L38: =G38-'2'!D38 -> 0 | M38: =L38*J38 -> 0
A39: 400 ml csd | B39: Coke | C39: 20 | F39: =E39*H39 -> 0 | G39: =D39+E39 -> 0 | H39: 399.19 | I39: =H39*D39 -> 0 | J39: 420 | K39: =J39*D39 -> 0 | L39: =G39-'2'!D39 -> 0 | M39: =L39*J39 -> 0
A40: 500 ml | B40: Kinley Water | C40: 9 | D40: 1 | F40: =E40*H40 -> 0 | G40: =D40+E40 -> 1 | H40: 174.19 | I40: =H40*D40 -> 174.19 | J40: 185 | K40: =J40*D40 -> 185 | L40: =G40-'2'!D40 -> 0 | M40: =L40*J40 -> 0
...

Sheet 2
A1: Pack | B1: Flavour | C1: MRP | D1: Stock PC | E1: Recived pc | F1: Recived invoice | G1: Total PC | H1: Invoce cost | I1: Amount | J1: sale price | K1: Amount | L1: SALE Pc | M1: SALE Amount
A2: 150 ml Tetra | B2: Mazza | C2: 9 | D2: 167 | E2: =42+336 -> 378 | F2: =E2*H2 -> 116473.14 | G2: =D2+E2 -> 545 | H2: 308.13 | I2: =H2*D2 -> 51457.71 | J2: 326 | K2: =J2*D2 -> 54442 | L2: =G2-'3'!D2 -> 38 | M2: =L2*J2 -> 12388
A3: 150 ml Tetra | B3: MM Apple | C3: 9 | D3: 71 | F3: =E3*H3 -> 0 | G3: =D3+E3 -> 71 | H3: 308.19 | I3: =H3*D3 -> 21881.49 | J3: 326 | K3: =J3*D3 -> 23146 | L3: =G3-'3'!D3 -> 3 | M3: =L3*J3 -> 978
A4: 150 ml Tetra | B4: MM LMN Fresh | C4: 9 | F4: =E4*H4 -> 0 | G4: =D4+E4 -> 0 | H4: 308.19 | I4: =H4*D4 -> 0 | J4: 326 | K4: =J4*D4 -> 0 | L4: =G4-'3'!D4 -> 0 | M4: =L4*J4 -> 0
A5: 200 ml RGB | B5: Thums up | C5: 10 | D5: 99 | E5: 144 | F5: =E5*H5 -> 25166.88 | G5: =D5+E5 -> 243 | H5: 174.77 | I5: =H5*D5 -> 17302.23 | J5: 192 | K5: =J5*D5 -> 19008 | L5: =G5-'3'!D5 -> 19 | M5: =L5*J5 -> 3648
A6: 200 ml RGB | B6: Sprite | C6: 10 | D6: 151 | E6: 72 | F6: =E6*H6 -> 12583.44 | G6: =D6+E6 -> 223 | H6: 174.77 | I6: =H6*D6 -> 26390.27 | J6: 192 | K6: =J6*D6 -> 28992 | L6: =G6-'3'!D6 -> 6 | M6: =L6*J6 -> 1152
A7: 200 ml RGB | B7: Limca | C7: 10 | D7: 64 | F7: =E7*H7 -> 0 | G7: =D7+E7 -> 64 | H7: 174.77 | I7: =H7*D7 -> 11185.28 | J7: 192 | K7: =J7*D7 -> 12288 | L7: =G7-'3'!D7 -> 4 | M7: =L7*J7 -> 768
A8: 200 ml RGB | B8: Fanta | C8: 10 | D8: 34 | E8: 72 | F8: =E8*H8 -> 12583.44 | G8: =D8+E8 -> 106 | H8: 174.77 | I8: =H8*D8 -> 5942.18 | J8: 192 | K8: =J8*D8 -> 6528 | L8: =G8-'3'!D8 -> 7 | M8: =L8*J8 -> 1344
A9: 200 ml RGB | B9: Coke | C9: 10 | D9: 216 | F9: =E9*H9 -> 0 | G9: =D9+E9 -> 216 | H9: 174.77 | I9: =H9*D9 -> 37750.32 | J9: 192 | K9: =J9*D9 -> 41472 | L9: =G9-'3'!D9 -> 4 | M9: =L9*J9 -> 768
A10: 200 ml RGB | B10: Mazza | C10: 14 | F10: =E10*H10 -> 0 | G10: =D10+E10 -> 0 | H10: 259.54 | I10: =H10*D10 -> 0 | J10: 282 | K10: =J10*D10 -> 0 | L10: =G10-'3'!D10 -> 0 | M10: =L10*J10 -> 0
A11: 250 ml PET | B11: Thums up Charge | C11: 20 | D11: 43 | F11: =E11*H11 -> 0 | G11: =D11+E11 -> 43 | H11: 470.8 | I11: =H11*D11 -> 20244.4 | J11: 505 | K11: =J11*D11 -> 21715 | L11: =G11-'3'!D11 -> 2 | M11: =L11*J11 -> 1010
A12: 250 ml PET | B12: Thums up | C12: 20 | D12: 484 | E12: 162 | F12: =E12*H12 -> 77074.74 | G12: =D12+E12 -> 646 | H12: 475.77 | I12: =H12*D12 -> 230272.68 | J12: 505 | K12: =J12*D12 -> 244420 | L12: =G12-'3'!D12 -> 93 | M12: =L12*J12 -> 46965
A13: 250 ml PET | B13: Sprite | C13: 20 | D13: 398 | F13: =E13*H13 -> 0 | G13: =D13+E13 -> 398 | H13: 475.77 | I13: =H13*D13 -> 189356.46 | J13: 505 | K13: =J13*D13 -> 200990 | L13: =G13-'3'!D13 -> 47 | M13: =L13*J13 -> 23735
A14: 250 ml PET | B14: Limca | C14: 20 | D14: 70 | F14: =E14*H14 -> 0 | G14: =D14+E14 -> 70 | H14: 470.8 | I14: =H14*D14 -> 32956 | J14: 505 | K14: =J14*D14 -> 35350 | L14: =G14-'3'!D14 -> 7 | M14: =L14*J14 -> 3535
A15: 250 ml PET | B15: Fanta | C15: 20 | D15: 65 | F15: =E15*H15 -> 0 | G15: =D15+E15 -> 65 | H15: 470.8 | I15: =H15*D15 -> 30602 | J15: 505 | K15: =J15*D15 -> 32825 | L15: =G15-'3'!D15 -> 7 | M15: =L15*J15 -> 3535
A16: 250 ml PET | B16: Coke | C16: 20 | D16: 2 | F16: =E16*H16 -> 0 | G16: =D16+E16 -> 2 | H16: 470.8 | I16: =H16*D16 -> 941.6 | J16: 505 | K16: =J16*D16 -> 1010 | L16: =G16-'3'!D16 -> 2 | M16: =L16*J16 -> 1010
A17: 250 ml PET | B17: Kinley Soda | C17: 11 | D17: 102 | F17: =E17*H17 -> 0 | G17: =D17+E17 -> 102 | H17: 235.59 | I17: =H17*D17 -> 24030.18 | J17: 250 | K17: =J17*D17 -> 25500 | L17: =G17-'3'!D17 -> 8 | M17: =L17*J17 -> 2000
A18: 250 ml PET | B18: RimZim Fiz | C18: 20 | F18: =E18*H18 -> 0 | G18: =D18+E18 -> 0 | H18: 470.8 | I18: =H18*D18 -> 0 | J18: 500 | K18: =J18*D18 -> 0 | L18: =G18-'3'!D18 -> 0 | M18: =L18*J18 -> 0
A19: 250 ml PET | B19: Zero Thums up | C19: 10 | F19: =E19*H19 -> 0 | G19: =D19+E19 -> 0 | H19: 204 | I19: =H19*D19 -> 0 | J19: 230 | K19: =J19*D19 -> 0 | L19: =G19-'3'!D19 -> 0 | M19: =L19*J19 -> 0
A20: 250 ml PET | B20: Zero Sprite | C20: 10 | F20: =E20*H20 -> 0 | G20: =D20+E20 -> 0 | H20: 204 | I20: =H20*D20 -> 0 | J20: 230 | K20: =J20*D20 -> 0 | L20: =G20-'3'!D20 -> 0 | M20: =L20*J20 -> 0
A21: 250 ml PET | B21: Zero Coke | C21: 10 | D21: 32 | F21: =E21*H21 -> 0 | G21: =D21+E21 -> 32 | H21: 204 | I21: =H21*D21 -> 6528 | J21: 230 | K21: =J21*D21 -> 7360 | L21: =G21-'3'!D21 -> 2 | M21: =L21*J21 -> 460
A22: 250 ml PET | B22: Mazza | C22: 19 | D22: 115 | F22: =E22*H22 -> 0 | G22: =D22+E22 -> 115 | H22: 474.46 | I22: =H22*D22 -> 54562.9 | J22: 505 | K22: =J22*D22 -> 58075 | L22: =G22-'3'!D22 -> 16 | M22: =L22*J22 -> 8080
A23: 250 ml PET | B23: MM Pulpy orange | C23: 24 | D23: 103 | F23: =E23*H23 -> 0 | G23: =D23+E23 -> 103 | H23: 593.92 | I23: =H23*D23 -> 61173.76 | J23: 630 | K23: =J23*D23 -> 64890 | L23: =G23-'3'!D23 -> 20 | M23: =L23*J23 -> 12600
A24: 300 ml RGB | B24: Thums up | C24: 25 | D24: 9 | E24: 54 | F24: =E24*H24 -> 24478.2 | G24: =D24+E24 -> 63 | H24: 453.3 | I24: =H24*D24 -> 4079.7 | J24: 493 | K24: =J24*D24 -> 4437 | L24: =G24-'3'!D24 -> 0 | M24: =L24*J24 -> 0
A25: 300 ml RGB | B25: Sprite | C25: 25 | E25: 54 | F25: =E25*H25 -> 24478.2 | G25: =D25+E25 -> 54 | H25: 453.3 | I25: =H25*D25 -> 0 | J25: 493 | K25: =J25*D25 -> 0 | L25: =G25-'3'!D25 -> 0 | M25: =L25*J25 -> 0
A26: 300 ml RGB | B26: Fanta | C26: 25 | F26: =E26*H26 -> 0 | G26: =D26+E26 -> 0 | H26: 453.3 | I26: =H26*D26 -> 0 | J26: 493 | K26: =J26*D26 -> 0 | L26: =G26-'3'!D26 -> 0 | M26: =L26*J26 -> 0
A27: 300 ml RGB | B27: Coke | C27: 25 | F27: =E27*H27 -> 0 | G27: =D27+E27 -> 0 | H27: 453.3 | I27: =H27*D27 -> 0 | J27: 493 | K27: =J27*D27 -> 0 | L27: =G27-'3'!D27 -> 0 | M27: =L27*J27 -> 0
A28: 300 ml CAN | B28: Thums up | C28: 40 | F28: =E28*H28 -> 0 | G28: =D28+E28 -> 0 | H28: 821.36 | I28: =H28*D28 -> 0 | J28: 878 | K28: =J28*D28 -> 0 | L28: =G28-'3'!D28 -> 0 | M28: =L28*J28 -> 0
A29: 300 ml CAN | B29: Sprite | C29: 40 | F29: =E29*H29 -> 0 | G29: =D29+E29 -> 0 | H29: 821.36 | I29: =H29*D29 -> 0 | J29: 878 | K29: =J29*D29 -> 0 | L29: =G29-'3'!D29 -> 0 | M29: =L29*J29 -> 0
A30: 300 ml CAN | B30: Limca | C30: 40 | F30: =E30*H30 -> 0 | G30: =D30+E30 -> 0 | H30: 817.58 | I30: =H30*D30 -> 0 | J30: 878 | K30: =J30*D30 -> 0 | L30: =G30-'3'!D30 -> 0 | M30: =L30*J30 -> 0
A31: 300 ml CAN | B31: Fanta | C31: 40 | F31: =E31*H31 -> 0 | G31: =D31+E31 -> 0 | H31: 817.58 | I31: =H31*D31 -> 0 | J31: 878 | K31: =J31*D31 -> 0 | L31: =G31-'3'!D31 -> 0 | M31: =L31*J31 -> 0
A32: 300 ml CAN | B32: Coke | C32: 40 | F32: =E32*H32 -> 0 | G32: =D32+E32 -> 0 | H32: 817.58 | I32: =H32*D32 -> 0 | J32: 878 | K32: =J32*D32 -> 0 | L32: =G32-'3'!D32 -> 0 | M32: =L32*J32 -> 0
A33: 300 ml CAN | B33: D'Coke | C33: 40 | F33: =E33*H33 -> 0 | G33: =D33+E33 -> 0 | H33: 817.58 | I33: =H33*D33 -> 0 | J33: 878 | K33: =J33*D33 -> 0 | L33: =G33-'3'!D33 -> 0 | M33: =L33*J33 -> 0
A34: 300 ml CAN | B34: Predator | C34: 60 | D34: 1 | E34: 143 | F34: =E34*H34 -> 149098.95 | G34: =D34+E34 -> 144 | H34: 1042.65 | I34: =H34*D34 -> 1042.65 | J34: 1110 | K34: =J34*D34 -> 1110 | L34: =G34-'3'!D34 -> 12 | M34: =L34*J34 -> 13320
A35: 300 ml | B35: Kinley Water | C35: 7 | D35: 16 | F35: =E35*H35 -> 0 | G35: =D35+E35 -> 16 | H35: 126.24 | I35: =H35*D35 -> 2019.84 | J35: 140 | K35: =J35*D35 -> 2240 | L35: =G35-'3'!D35 -> 0 | M35: =L35*J35 -> 0
A36: 350 ml CAN | B36: Monster | C36: 125 | D36: 3 | E36: 39 | F36: =E36*H36 -> 79971.06 | G36: =D36+E36 -> 42 | H36: 2050.54 | I36: =H36*D36 -> 6151.62 | J36: 2175 | K36: =J36*D36 -> 6525 | L36: =G36-'3'!D36 -> 4 | M36: =L36*J36 -> 8700
A37: 400 ml csd | B37: Thums up | C37: 20 | D37: 3 | F37: =E37*H37 -> 0 | G37: =D37+E37 -> 3 | H37: 399.19 | I37: =H37*D37 -> 1197.57 | J37: 420 | K37: =J37*D37 -> 1260 | L37: =G37-'3'!D37 -> 1 | M37: =L37*J37 -> 420
A38: 400 ml csd | B38: Sprite | C38: 20 | F38: =E38*H38 -> 0 | G38: =D38+E38 -> 0 | H38: 399.19 | I38: =H38*D38 -> 0 | J38: 420 | K38: =J38*D38 -> 0 | L38: =G38-'3'!D38 -> 0 | M38: =L38*J38 -> 0
A39: 400 ml csd | B39: Coke | C39: 20 | F39: =E39*H39 -> 0 | G39: =D39+E39 -> 0 | H39: 399.19 | I39: =H39*D39 -> 0 | J39: 420 | K39: =J39*D39 -> 0 | L39: =G39-'3'!D39 -> 0 | M39: =L39*J39 -> 0
A40: 500 ml | B40: Kinley Water | C40: 9 | D40: 1 | E40: 72 | F40: =E40*H40 -> 12541.68 | G40: =D40+E40 -> 73 | H40: 174.19 | I40: =H40*D40 -> 174.19 | J40: 185 | K40: =J40*D40 -> 185 | L40: =G40-'3'!D40 -> 0 | M40: =L40*J40 -> 0
...

Sheet 3
A1: Pack | B1: Flavour | C1: MRP | D1: Stock PC | E1: Recived pc | F1: Recived invoice | G1: Total PC | H1: Invoce cost | I1: Amount | J1: sale price | K1: Amount | L1: SALE Pc | M1: SALE Amount
A2: 150 ml Tetra | B2: Mazza | C2: 9 | D2: 507 | F2: =E2*H2 -> 0 | G2: =D2+E2 -> 507 | H2: 308.13 | I2: =H2*D2 -> 156221.91 | J2: 326 | K2: =J2*D2 -> 165282 | L2: =G2-'4'!D2 -> 15 | M2: =L2*J2 -> 4890
A3: 150 ml Tetra | B3: MM Apple | C3: 9 | D3: 68 | F3: =E3*H3 -> 0 | G3: =D3+E3 -> 68 | H3: 308.19 | I3: =H3*D3 -> 20956.92 | J3: 326 | K3: =J3*D3 -> 22168 | L3: =G3-'4'!D3 -> 1 | M3: =L3*J3 -> 326
A4: 150 ml Tetra | B4: MM LMN Fresh | C4: 9 | F4: =E4*H4 -> 0 | G4: =D4+E4 -> 0 | H4: 308.19 | I4: =H4*D4 -> 0 | J4: 326 | K4: =J4*D4 -> 0 | L4: =G4-'4'!D4 -> 0 | M4: =L4*J4 -> 0
A5: 200 ml RGB | B5: Thums up | C5: 10 | D5: 224 | F5: =E5*H5 -> 0 | G5: =D5+E5 -> 224 | H5: 174.77 | I5: =H5*D5 -> 39148.48 | J5: 192 | K5: =J5*D5 -> 43008 | L5: =G5-'4'!D5 -> 18 | M5: =L5*J5 -> 3456
A6: 200 ml RGB | B6: Sprite | C6: 10 | D6: 217 | F6: =E6*H6 -> 0 | G6: =D6+E6 -> 217 | H6: 174.77 | I6: =H6*D6 -> 37925.09 | J6: 192 | K6: =J6*D6 -> 41664 | L6: =G6-'4'!D6 -> 11 | M6: =L6*J6 -> 2112
A7: 200 ml RGB | B7: Limca | C7: 10 | D7: 60 | F7: =E7*H7 -> 0 | G7: =D7+E7 -> 60 | H7: 174.77 | I7: =H7*D7 -> 10486.2 | J7: 192 | K7: =J7*D7 -> 11520 | L7: =G7-'4'!D7 -> 3 | M7: =L7*J7 -> 576
A8: 200 ml RGB | B8: Fanta | C8: 10 | D8: 99 | F8: =E8*H8 -> 0 | G8: =D8+E8 -> 99 | H8: 174.77 | I8: =H8*D8 -> 17302.23 | J8: 192 | K8: =J8*D8 -> 19008 | L8: =G8-'4'!D8 -> 6 | M8: =L8*J8 -> 1152
A9: 200 ml RGB | B9: Coke | C9: 10 | D9: 212 | F9: =E9*H9 -> 0 | G9: =D9+E9 -> 212 | H9: 174.77 | I9: =H9*D9 -> 37051.24 | J9: 192 | K9: =J9*D9 -> 40704 | L9: =G9-'4'!D9 -> 12 | M9: =L9*J9 -> 2304
A10: 200 ml RGB | B10: Mazza | C10: 14 | F10: =E10*H10 -> 0 | G10: =D10+E10 -> 0 | H10: 259.54 | I10: =H10*D10 -> 0 | J10: 282 | K10: =J10*D10 -> 0 | L10: =G10-'4'!D10 -> 0 | M10: =L10*J10 -> 0
A11: 250 ml PET | B11: Thums up Charge | C11: 20 | D11: 41 | F11: =E11*H11 -> 0 | G11: =D11+E11 -> 41 | H11: 470.8 | I11: =H11*D11 -> 19302.8 | J11: 505 | K11: =J11*D11 -> 20705 | L11: =G11-'4'!D11 -> 2 | M11: =L11*J11 -> 1010
A12: 250 ml PET | B12: Thums up | C12: 20 | D12: 553 | F12: =E12*H12 -> 0 | G12: =D12+E12 -> 553 | H12: 475.77 | I12: =H12*D12 -> 263100.81 | J12: 505 | K12: =J12*D12 -> 279265 | L12: =G12-'4'!D12 -> 69 | M12: =L12*J12 -> 34845
A13: 250 ml PET | B13: Sprite | C13: 20 | D13: 351 | F13: =E13*H13 -> 0 | G13: =D13+E13 -> 351 | H13: 475.77 | I13: =H13*D13 -> 166995.27 | J13: 505 | K13: =J13*D13 -> 177255 | L13: =G13-'4'!D13 -> 34 | M13: =L13*J13 -> 17170
A14: 250 ml PET | B14: Limca | C14: 20 | D14: 63 | F14: =E14*H14 -> 0 | G14: =D14+E14 -> 63 | H14: 470.8 | I14: =H14*D14 -> 29660.4 | J14: 505 | K14: =J14*D14 -> 31815 | L14: =G14-'4'!D14 -> 9 | M14: =L14*J14 -> 4545
A15: 250 ml PET | B15: Fanta | C15: 20 | D15: 58 | F15: =E15*H15 -> 0 | G15: =D15+E15 -> 58 | H15: 470.8 | I15: =H15*D15 -> 27306.4 | J15: 505 | K15: =J15*D15 -> 29290 | L15: =G15-'4'!D15 -> 9 | M15: =L15*J15 -> 4545
A16: 250 ml PET | B16: Coke | C16: 20 | F16: =E16*H16 -> 0 | G16: =D16+E16 -> 0 | H16: 470.8 | I16: =H16*D16 -> 0 | J16: 505 | K16: =J16*D16 -> 0 | L16: =G16-'4'!D16 -> 0 | M16: =L16*J16 -> 0
A17: 250 ml PET | B17: Kinley Soda | C17: 11 | D17: 94 | F17: =E17*H17 -> 0 | G17: =D17+E17 -> 94 | H17: 235.59 | I17: =H17*D17 -> 22145.46 | J17: 250 | K17: =J17*D17 -> 23500 | L17: =G17-'4'!D17 -> 7 | M17: =L17*J17 -> 1750
A18: 250 ml PET | B18: RimZim Fiz | C18: 20 | F18: =E18*H18 -> 0 | G18: =D18+E18 -> 0 | H18: 470.8 | I18: =H18*D18 -> 0 | J18: 500 | K18: =J18*D18 -> 0 | L18: =G18-'4'!D18 -> 0 | M18: =L18*J18 -> 0
A19: 250 ml PET | B19: Zero Thums up | C19: 10 | F19: =E19*H19 -> 0 | G19: =D19+E19 -> 0 | H19: 204 | I19: =H19*D19 -> 0 | J19: 230 | K19: =J19*D19 -> 0 | L19: =G19-'4'!D19 -> 0 | M19: =L19*J19 -> 0
A20: 250 ml PET | B20: Zero Sprite | C20: 10 | F20: =E20*H20 -> 0 | G20: =D20+E20 -> 0 | H20: 204 | I20: =H20*D20 -> 0 | J20: 230 | K20: =J20*D20 -> 0 | L20: =G20-'4'!D20 -> 0 | M20: =L20*J20 -> 0
A21: 250 ml PET | B21: Zero Coke | C21: 10 | D21: 30 | F21: =E21*H21 -> 0 | G21: =D21+E21 -> 30 | H21: 204 | I21: =H21*D21 -> 6120 | J21: 230 | K21: =J21*D21 -> 6900 | L21: =G21-'4'!D21 -> 0 | M21: =L21*J21 -> 0
A22: 250 ml PET | B22: Mazza | C22: 19 | D22: 99 | F22: =E22*H22 -> 0 | G22: =D22+E22 -> 99 | H22: 474.46 | I22: =H22*D22 -> 46971.54 | J22: 505 | K22: =J22*D22 -> 49995 | L22: =G22-'4'!D22 -> 22 | M22: =L22*J22 -> 11110
A23: 250 ml PET | B23: MM Pulpy orange | C23: 24 | D23: 83 | F23: =E23*H23 -> 0 | G23: =D23+E23 -> 83 | H23: 593.92 | I23: =H23*D23 -> 49295.36 | J23: 630 | K23: =J23*D23 -> 52290 | L23: =G23-'4'!D23 -> 16 | M23: =L23*J23 -> 10080
A24: 300 ml RGB | B24: Thums up | C24: 25 | D24: 63 | F24: =E24*H24 -> 0 | G24: =D24+E24 -> 63 | H24: 453.3 | I24: =H24*D24 -> 28557.9 | J24: 493 | K24: =J24*D24 -> 31059 | L24: =G24-'4'!D24 -> 0 | M24: =L24*J24 -> 0
A25: 300 ml RGB | B25: Sprite | C25: 25 | D25: 54 | F25: =E25*H25 -> 0 | G25: =D25+E25 -> 54 | H25: 453.3 | I25: =H25*D25 -> 24478.2 | J25: 493 | K25: =J25*D25 -> 26622 | L25: =G25-'4'!D25 -> 0 | M25: =L25*J25 -> 0
A26: 300 ml RGB | B26: Fanta | C26: 25 | F26: =E26*H26 -> 0 | G26: =D26+E26 -> 0 | H26: 453.3 | I26: =H26*D26 -> 0 | J26: 493 | K26: =J26*D26 -> 0 | L26: =G26-'4'!D26 -> 0 | M26: =L26*J26 -> 0
A27: 300 ml RGB | B27: Coke | C27: 25 | F27: =E27*H27 -> 0 | G27: =D27+E27 -> 0 | H27: 453.3 | I27: =H27*D27 -> 0 | J27: 493 | K27: =J27*D27 -> 0 | L27: =G27-'4'!D27 -> 0 | M27: =L27*J27 -> 0
A28: 300 ml CAN | B28: Thums up | C28: 40 | F28: =E28*H28 -> 0 | G28: =D28+E28 -> 0 | H28: 821.36 | I28: =H28*D28 -> 0 | J28: 878 | K28: =J28*D28 -> 0 | L28: =G28-'4'!D28 -> 0 | M28: =L28*J28 -> 0
A29: 300 ml CAN | B29: Sprite | C29: 40 | F29: =E29*H29 -> 0 | G29: =D29+E29 -> 0 | H29: 821.36 | I29: =H29*D29 -> 0 | J29: 878 | K29: =J29*D29 -> 0 | L29: =G29-'4'!D29 -> 0 | M29: =L29*J29 -> 0
A30: 300 ml CAN | B30: Limca | C30: 40 | F30: =E30*H30 -> 0 | G30: =D30+E30 -> 0 | H30: 817.58 | I30: =H30*D30 -> 0 | J30: 878 | K30: =J30*D30 -> 0 | L30: =G30-'4'!D30 -> 0 | M30: =L30*J30 -> 0
A31: 300 ml CAN | B31: Fanta | C31: 40 | F31: =E31*H31 -> 0 | G31: =D31+E31 -> 0 | H31: 817.58 | I31: =H31*D31 -> 0 | J31: 878 | K31: =J31*D31 -> 0 | L31: =G31-'4'!D31 -> 0 | M31: =L31*J31 -> 0
A32: 300 ml CAN | B32: Coke | C32: 40 | F32: =E32*H32 -> 0 | G32: =D32+E32 -> 0 | H32: 817.58 | I32: =H32*D32 -> 0 | J32: 878 | K32: =J32*D32 -> 0 | L32: =G32-'4'!D32 -> 0 | M32: =L32*J32 -> 0
A33: 300 ml CAN | B33: D'Coke | C33: 40 | F33: =E33*H33 -> 0 | G33: =D33+E33 -> 0 | H33: 817.58 | I33: =H33*D33 -> 0 | J33: 878 | K33: =J33*D33 -> 0 | L33: =G33-'4'!D33 -> 0 | M33: =L33*J33 -> 0
A34: 300 ml CAN | B34: Predator | C34: 60 | D34: 132 | F34: =E34*H34 -> 0 | G34: =D34+E34 -> 132 | H34: 1042.65 | I34: =H34*D34 -> 137629.8 | J34: 1110 | K34: =J34*D34 -> 146520 | L34: =G34-'4'!D34 -> 86 | M34: =L34*J34 -> 95460
A35: 300 ml | B35: Kinley Water | C35: 7 | D35: 16 | F35: =E35*H35 -> 0 | G35: =D35+E35 -> 16 | H35: 126.24 | I35: =H35*D35 -> 2019.84 | J35: 140 | K35: =J35*D35 -> 2240 | L35: =G35-'4'!D35 -> 1 | M35: =L35*J35 -> 140
A36: 350 ml CAN | B36: Monster | C36: 125 | D36: 38 | F36: =E36*H36 -> 0 | G36: =D36+E36 -> 38 | H36: 2050.54 | I36: =H36*D36 -> 77920.52 | J36: 2175 | K36: =J36*D36 -> 82650 | L36: =G36-'4'!D36 -> 17 | M36: =L36*J36 -> 36975
A37: 400 ml csd | B37: Thums up | C37: 20 | D37: 2 | F37: =E37*H37 -> 0 | G37: =D37+E37 -> 2 | H37: 399.19 | I37: =H37*D37 -> 798.38 | J37: 420 | K37: =J37*D37 -> 840 | L37: =G37-'4'!D37 -> 0 | M37: =L37*J37 -> 0
A38: 400 ml csd | B38: Sprite | C38: 20 | F38: =E38*H38 -> 0 | G38: =D38+E38 -> 0 | H38: 399.19 | I38: =H38*D38 -> 0 | J38: 420 | K38: =J38*D38 -> 0 | L38: =G38-'4'!D38 -> 0 | M38: =L38*J38 -> 0
A39: 400 ml csd | B39: Coke | C39: 20 | F39: =E39*H39 -> 0 | G39: =D39+E39 -> 0 | H39: 399.19 | I39: =H39*D39 -> 0 | J39: 420 | K39: =J39*D39 -> 0 | L39: =G39-'4'!D39 -> 0 | M39: =L39*J39 -> 0
A40: 500 ml | B40: Kinley Water | C40: 9 | D40: 73 | F40: =E40*H40 -> 0 | G40: =D40+E40 -> 73 | H40: 174.19 | I40: =H40*D40 -> 12715.87 | J40: 185 | K40: =J40*D40 -> 13505 | L40: =G40-'4'!D40 -> 0 | M40: =L40*J40 -> 0
...

Sheet 4
A1: Pack | B1: Flavour | C1: MRP | D1: Stock PC | E1: Recived pc | F1: Recived invoice | G1: Total PC | H1: Invoce cost | I1: Amount | J1: sale price | K1: Amount | L1: SALE Pc | M1: SALE Amount
A2: 150 ml Tetra | B2: Mazza | C2: 9 | D2: 492 | F2: =E2*H2 -> 0 | G2: =D2+E2 -> 492 | H2: 308.13 | I2: =H2*D2 -> 151599.96 | J2: 326 | K2: =J2*D2 -> 160392 | L2: 0 | M2: =L2*J2 -> 0
A3: 150 ml Tetra | B3: MM Apple | C3: 9 | D3: 67 | F3: =E3*H3 -> 0 | G3: =D3+E3 -> 67 | H3: 308.19 | I3: =H3*D3 -> 20648.73 | J3: 326 | K3: =J3*D3 -> 21842 | L3: 0 | M3: =L3*J3 -> 0
A4: 150 ml Tetra | B4: MM LMN Fresh | C4: 9 | F4: =E4*H4 -> 0 | G4: =D4+E4 -> 0 | H4: 308.19 | I4: =H4*D4 -> 0 | J4: 326 | K4: =J4*D4 -> 0 | L4: 0 | M4: =L4*J4 -> 0
A5: 200 ml RGB | B5: Thums up | C5: 10 | D5: 206 | F5: =E5*H5 -> 0 | G5: =D5+E5 -> 206 | H5: 174.77 | I5: =H5*D5 -> 36002.62 | J5: 192 | K5: =J5*D5 -> 39552 | L5: 0 | M5: =L5*J5 -> 0
A6: 200 ml RGB | B6: Sprite | C6: 10 | D6: 206 | F6: =E6*H6 -> 0 | G6: =D6+E6 -> 206 | H6: 174.77 | I6: =H6*D6 -> 36002.62 | J6: 192 | K6: =J6*D6 -> 39552 | L6: 0 | M6: =L6*J6 -> 0
A7: 200 ml RGB | B7: Limca | C7: 10 | D7: 57 | F7: =E7*H7 -> 0 | G7: =D7+E7 -> 57 | H7: 174.77 | I7: =H7*D7 -> 9961.89 | J7: 192 | K7: =J7*D7 -> 10944 | L7: 0 | M7: =L7*J7 -> 0
A8: 200 ml RGB | B8: Fanta | C8: 10 | D8: 93 | F8: =E8*H8 -> 0 | G8: =D8+E8 -> 93 | H8: 174.77 | I8: =H8*D8 -> 16253.61 | J8: 192 | K8: =J8*D8 -> 17856 | L8: 0 | M8: =L8*J8 -> 0
A9: 200 ml RGB | B9: Coke | C9: 10 | D9: 200 | F9: =E9*H9 -> 0 | G9: =D9+E9 -> 200 | H9: 174.77 | I9: =H9*D9 -> 34954 | J9: 192 | K9: =J9*D9 -> 38400 | L9: 0 | M9: =L9*J9 -> 0
A10: 200 ml RGB | B10: Mazza | C10: 14 | F10: =E10*H10 -> 0 | G10: =D10+E10 -> 0 | H10: 259.54 | I10: =H10*D10 -> 0 | J10: 282 | K10: =J10*D10 -> 0 | L10: 0 | M10: =L10*J10 -> 0
A11: 250 ml PET | B11: Thums up Charge | C11: 20 | D11: 39 | F11: =E11*H11 -> 0 | G11: =D11+E11 -> 39 | H11: 470.8 | I11: =H11*D11 -> 18361.2 | J11: 505 | K11: =J11*D11 -> 19695 | L11: 0 | M11: =L11*J11 -> 0
A12: 250 ml PET | B12: Thums up | C12: 20 | D12: 484 | F12: =E12*H12 -> 0 | G12: =D12+E12 -> 484 | H12: 475.77 | I12: =H12*D12 -> 230272.68 | J12: 505 | K12: =J12*D12 -> 244420 | L12: 0 | M12: =L12*J12 -> 0
A13: 250 ml PET | B13: Sprite | C13: 20 | D13: 317 | F13: =E13*H13 -> 0 | G13: =D13+E13 -> 317 | H13: 475.77 | I13: =H13*D13 -> 150819.09 | J13: 505 | K13: =J13*D13 -> 160085 | L13: 0 | M13: =L13*J13 -> 0
A14: 250 ml PET | B14: Limca | C14: 20 | D14: 54 | F14: =E14*H14 -> 0 | G14: =D14+E14 -> 54 | H14: 470.8 | I14: =H14*D14 -> 25423.2 | J14: 505 | K14: =J14*D14 -> 27270 | L14: 0 | M14: =L14*J14 -> 0
A15: 250 ml PET | B15: Fanta | C15: 20 | D15: 49 | F15: =E15*H15 -> 0 | G15: =D15+E15 -> 49 | H15: 470.8 | I15: =H15*D15 -> 23069.2 | J15: 505 | K15: =J15*D15 -> 24745 | L15: 0 | M15: =L15*J15 -> 0
A16: 250 ml PET | B16: Coke | C16: 20 | F16: =E16*H16 -> 0 | G16: =D16+E16 -> 0 | H16: 470.8 | I16: =H16*D16 -> 0 | J16: 505 | K16: =J16*D16 -> 0 | L16: 0 | M16: =L16*J16 -> 0
A17: 250 ml PET | B17: Kinley Soda | C17: 11 | D17: 87 | F17: =E17*H17 -> 0 | G17: =D17+E17 -> 87 | H17: 235.59 | I17: =H17*D17 -> 20496.33 | J17: 250 | K17: =J17*D17 -> 21750 | L17: 0 | M17: =L17*J17 -> 0
A18: 250 ml PET | B18: RimZim Fiz | C18: 20 | F18: =E18*H18 -> 0 | G18: =D18+E18 -> 0 | H18: 470.8 | I18: =H18*D18 -> 0 | J18: 500 | K18: =J18*D18 -> 0 | L18: 0 | M18: =L18*J18 -> 0
A19: 250 ml PET | B19: Zero Thums up | C19: 10 | F19: =E19*H19 -> 0 | G19: =D19+E19 -> 0 | H19: 204 | I19: =H19*D19 -> 0 | J19: 230 | K19: =J19*D19 -> 0 | L19: 0 | M19: =L19*J19 -> 0
A20: 250 ml PET | B20: Zero Sprite | C20: 10 | F20: =E20*H20 -> 0 | G20: =D20+E20 -> 0 | H20: 204 | I20: =H20*D20 -> 0 | J20: 230 | K20: =J20*D20 -> 0 | L20: 0 | M20: =L20*J20 -> 0
A21: 250 ml PET | B21: Zero Coke | C21: 10 | D21: 30 | F21: =E21*H21 -> 0 | G21: =D21+E21 -> 30 | H21: 204 | I21: =H21*D21 -> 6120 | J21: 230 | K21: =J21*D21 -> 6900 | L21: 0 | M21: =L21*J21 -> 0
A22: 250 ml PET | B22: Mazza | C22: 19 | D22: 77 | F22: =E22*H22 -> 0 | G22: =D22+E22 -> 77 | H22: 474.46 | I22: =H22*D22 -> 36533.42 | J22: 505 | K22: =J22*D22 -> 38885 | L22: 0 | M22: =L22*J22 -> 0
A23: 250 ml PET | B23: MM Pulpy orange | C23: 24 | D23: 67 | F23: =E23*H23 -> 0 | G23: =D23+E23 -> 67 | H23: 593.92 | I23: =H23*D23 -> 39792.64 | J23: 630 | K23: =J23*D23 -> 42210 | L23: 0 | M23: =L23*J23 -> 0
A24: 300 ml RGB | B24: Thums up | C24: 25 | D24: 63 | F24: =E24*H24 -> 0 | G24: =D24+E24 -> 63 | H24: 453.3 | I24: =H24*D24 -> 28557.9 | J24: 493 | K24: =J24*D24 -> 31059 | L24: 0 | M24: =L24*J24 -> 0
A25: 300 ml RGB | B25: Sprite | C25: 25 | D25: 54 | F25: =E25*H25 -> 0 | G25: =D25+E25 -> 54 | H25: 453.3 | I25: =H25*D25 -> 24478.2 | J25: 493 | K25: =J25*D25 -> 26622 | L25: 0 | M25: =L25*J25 -> 0
A26: 300 ml RGB | B26: Fanta | C26: 25 | F26: =E26*H26 -> 0 | G26: =D26+E26 -> 0 | H26: 453.3 | I26: =H26*D26 -> 0 | J26: 493 | K26: =J26*D26 -> 0 | L26: 0 | M26: =L26*J26 -> 0
A27: 300 ml RGB | B27: Coke | C27: 25 | F27: =E27*H27 -> 0 | G27: =D27+E27 -> 0 | H27: 453.3 | I27: =H27*D27 -> 0 | J27: 493 | K27: =J27*D27 -> 0 | L27: 0 | M27: =L27*J27 -> 0
A28: 300 ml CAN | B28: Thums up | C28: 40 | F28: =E28*H28 -> 0 | G28: =D28+E28 -> 0 | H28: 821.36 | I28: =H28*D28 -> 0 | J28: 878 | K28: =J28*D28 -> 0 | L28: 0 | M28: =L28*J28 -> 0
A29: 300 ml CAN | B29: Sprite | C29: 40 | F29: =E29*H29 -> 0 | G29: =D29+E29 -> 0 | H29: 821.36 | I29: =H29*D29 -> 0 | J29: 878 | K29: =J29*D29 -> 0 | L29: 0 | M29: =L29*J29 -> 0
A30: 300 ml CAN | B30: Limca | C30: 40 | F30: =E30*H30 -> 0 | G30: =D30+E30 -> 0 | H30: 817.58 | I30: =H30*D30 -> 0 | J30: 878 | K30: =J30*D30 -> 0 | L30: 0 | M30: =L30*J30 -> 0
A31: 300 ml CAN | B31: Fanta | C31: 40 | F31: =E31*H31 -> 0 | G31: =D31+E31 -> 0 | H31: 817.58 | I31: =H31*D31 -> 0 | J31: 878 | K31: =J31*D31 -> 0 | L31: 0 | M31: =L31*J31 -> 0
A32: 300 ml CAN | B32: Coke | C32: 40 | F32: =E32*H32 -> 0 | G32: =D32+E32 -> 0 | H32: 817.58 | I32: =H32*D32 -> 0 | J32: 878 | K32: =J32*D32 -> 0 | L32: 0 | M32: =L32*J32 -> 0
A33: 300 ml CAN | B33: D'Coke | C33: 40 | F33: =E33*H33 -> 0 | G33: =D33+E33 -> 0 | H33: 817.58 | I33: =H33*D33 -> 0 | J33: 878 | K33: =J33*D33 -> 0 | L33: 0 | M33: =L33*J33 -> 0
A34: 300 ml CAN | B34: Predator | C34: 60 | D34: 46 | F34: =E34*H34 -> 0 | G34: =D34+E34 -> 46 | H34: 1042.65 | I34: =H34*D34 -> 47961.9 | J34: 1110 | K34: =J34*D34 -> 51060 | L34: 0 | M34: =L34*J34 -> 0
A35: 300 ml | B35: Kinley Water | C35: 7 | D35: 15 | F35: =E35*H35 -> 0 | G35: =D35+E35 -> 15 | H35: 126.24 | I35: =H35*D35 -> 1893.6 | J35: 140 | K35: =J35*D35 -> 2100 | L35: 0 | M35: =L35*J35 -> 0
A36: 350 ml CAN | B36: Monster | C36: 125 | D36: 21 | F36: =E36*H36 -> 0 | G36: =D36+E36 -> 21 | H36: 2050.54 | I36: =H36*D36 -> 43061.34 | J36: 2175 | K36: =J36*D36 -> 45675 | L36: 0 | M36: =L36*J36 -> 0
A37: 400 ml csd | B37: Thums up | C37: 20 | D37: 2 | F37: =E37*H37 -> 0 | G37: =D37+E37 -> 2 | H37: 399.19 | I37: =H37*D37 -> 798.38 | J37: 420 | K37: =J37*D37 -> 840 | L37: 0 | M37: =L37*J37 -> 0
A38: 400 ml csd | B38: Sprite | C38: 20 | F38: =E38*H38 -> 0 | G38: =D38+E38 -> 0 | H38: 399.19 | I38: =H38*D38 -> 0 | J38: 420 | K38: =J38*D38 -> 0 | L38: 0 | M38: =L38*J38 -> 0
A39: 400 ml csd | B39: Coke | C39: 20 | F39: =E39*H39 -> 0 | G39: =D39+E39 -> 0 | H39: 399.19 | I39: =H39*D39 -> 0 | J39: 420 | K39: =J39*D39 -> 0 | L39: 0 | M39: =L39*J39 -> 0
A40: 500 ml | B40: Kinley Water | C40: 9 | D40: 73 | F40: =E40*H40 -> 0 | G40: =D40+E40 -> 73 | H40: 174.19 | I40: =H40*D40 -> 12715.87 | J40: 185 | K40: =J40*D40 -> 13505 | L40: 0 | M40: =L40*J40 -> 0
...

Sheet 5
A1: Pack | B1: Flavour | C1: MRP | D1: Stock PC | E1: Recived pc | F1: Recived invoice | G1: Total PC | H1: Invoce cost | I1: Amount | J1: sale price | K1: Amount | L1: SALE Pc | M1: SALE Amount
A2: 150 ml Tetra | B2: Mazza | C2: 9 | D2: 492 | F2: =E2*H2 -> 0 | G2: =D2+E2 -> 492 | H2: 308.13 | I2: =H2*D2 -> 151599.96 | J2: 326 | K2: =J2*D2 -> 160392 | L2: =G2-'6'!D2 -> 11 | M2: =L2*J2 -> 3586
A3: 150 ml Tetra | B3: MM Apple | C3: 9 | D3: 67 | F3: =E3*H3 -> 0 | G3: =D3+E3 -> 67 | H3: 308.19 | I3: =H3*D3 -> 20648.73 | J3: 326 | K3: =J3*D3 -> 21842 | L3: =G3-'6'!D3 -> 1 | M3: =L3*J3 -> 326
A4: 150 ml Tetra | B4: MM LMN Fresh | C4: 9 | F4: =E4*H4 -> 0 | G4: =D4+E4 -> 0 | H4: 308.19 | I4: =H4*D4 -> 0 | J4: 326 | K4: =J4*D4 -> 0 | L4: =G4-'6'!D4 -> 0 | M4: =L4*J4 -> 0
A5: 200 ml RGB | B5: Thums up | C5: 10 | D5: 206 | F5: =E5*H5 -> 0 | G5: =D5+E5 -> 206 | H5: 174.77 | I5: =H5*D5 -> 36002.62 | J5: 192 | K5: =J5*D5 -> 39552 | L5: =G5-'6'!D5 -> 22 | M5: =L5*J5 -> 4224
A6: 200 ml RGB | B6: Sprite | C6: 10 | D6: 206 | F6: =E6*H6 -> 0 | G6: =D6+E6 -> 206 | H6: 174.77 | I6: =H6*D6 -> 36002.62 | J6: 192 | K6: =J6*D6 -> 39552 | L6: =G6-'6'!D6 -> 14 | M6: =L6*J6 -> 2688
A7: 200 ml RGB | B7: Limca | C7: 10 | D7: 57 | F7: =E7*H7 -> 0 | G7: =D7+E7 -> 57 | H7: 174.77 | I7: =H7*D7 -> 9961.89 | J7: 192 | K7: =J7*D7 -> 10944 | L7: =G7-'6'!D7 -> 5 | M7: =L7*J7 -> 960
A8: 200 ml RGB | B8: Fanta | C8: 10 | D8: 93 | F8: =E8*H8 -> 0 | G8: =D8+E8 -> 93 | H8: 174.77 | I8: =H8*D8 -> 16253.61 | J8: 192 | K8: =J8*D8 -> 17856 | L8: =G8-'6'!D8 -> 10 | M8: =L8*J8 -> 1920
A9: 200 ml RGB | B9: Coke | C9: 10 | D9: 200 | F9: =E9*H9 -> 0 | G9: =D9+E9 -> 200 | H9: 174.77 | I9: =H9*D9 -> 34954 | J9: 192 | K9: =J9*D9 -> 38400 | L9: =G9-'6'!D9 -> 20 | M9: =L9*J9 -> 3840
A10: 200 ml RGB | B10: Mazza | C10: 14 | F10: =E10*H10 -> 0 | G10: =D10+E10 -> 0 | H10: 259.54 | I10: =H10*D10 -> 0 | J10: 282 | K10: =J10*D10 -> 0 | L10: =G10-'6'!D10 -> 0 | M10: =L10*J10 -> 0
A11: 250 ml PET | B11: Thums up Charge | C11: 20 | D11: 39 | F11: =E11*H11 -> 0 | G11: =D11+E11 -> 39 | H11: 470.8 | I11: =H11*D11 -> 18361.2 | J11: 505 | K11: =J11*D11 -> 19695 | L11: =G11-'6'!D11 -> 2 | M11: =L11*J11 -> 1010
A12: 250 ml PET | B12: Thums up | C12: 20 | D12: 484 | F12: =E12*H12 -> 0 | G12: =D12+E12 -> 484 | H12: 475.77 | I12: =H12*D12 -> 230272.68 | J12: 505 | K12: =J12*D12 -> 244420 | L12: =G12-'6'!D12 -> 71 | M12: =L12*J12 -> 35855
A13: 250 ml PET | B13: Sprite | C13: 20 | D13: 317 | F13: =E13*H13 -> 0 | G13: =D13+E13 -> 317 | H13: 475.77 | I13: =H13*D13 -> 150819.09 | J13: 505 | K13: =J13*D13 -> 160085 | L13: =G13-'6'!D13 -> 39 | M13: =L13*J13 -> 19695
A14: 250 ml PET | B14: Limca | C14: 20 | D14: 54 | F14: =E14*H14 -> 0 | G14: =D14+E14 -> 54 | H14: 470.8 | I14: =H14*D14 -> 25423.2 | J14: 505 | K14: =J14*D14 -> 27270 | L14: =G14-'6'!D14 -> 8 | M14: =L14*J14 -> 4040
A15: 250 ml PET | B15: Fanta | C15: 20 | D15: 49 | F15: =E15*H15 -> 0 | G15: =D15+E15 -> 49 | H15: 470.8 | I15: =H15*D15 -> 23069.2 | J15: 505 | K15: =J15*D15 -> 24745 | L15: =G15-'6'!D15 -> 2 | M15: =L15*J15 -> 1010
A16: 250 ml PET | B16: Coke | C16: 20 | F16: =E16*H16 -> 0 | G16: =D16+E16 -> 0 | H16: 470.8 | I16: =H16*D16 -> 0 | J16: 505 | K16: =J16*D16 -> 0 | L16: =G16-'6'!D16 -> 0 | M16: =L16*J16 -> 0
A17: 250 ml PET | B17: Kinley Soda | C17: 11 | D17: 87 | F17: =E17*H17 -> 0 | G17: =D17+E17 -> 87 | H17: 235.59 | I17: =H17*D17 -> 20496.33 | J17: 250 | K17: =J17*D17 -> 21750 | L17: =G17-'6'!D17 -> 7 | M17: =L17*J17 -> 1750
A18: 250 ml PET | B18: RimZim Fiz | C18: 20 | F18: =E18*H18 -> 0 | G18: =D18+E18 -> 0 | H18: 470.8 | I18: =H18*D18 -> 0 | J18: 500 | K18: =J18*D18 -> 0 | L18: =G18-'6'!D18 -> 0 | M18: =L18*J18 -> 0
A19: 250 ml PET | B19: Zero Thums up | C19: 10 | F19: =E19*H19 -> 0 | G19: =D19+E19 -> 0 | H19: 204 | I19: =H19*D19 -> 0 | J19: 230 | K19: =J19*D19 -> 0 | L19: =G19-'6'!D19 -> 0 | M19: =L19*J19 -> 0
A20: 250 ml PET | B20: Zero Sprite | C20: 10 | F20: =E20*H20 -> 0 | G20: =D20+E20 -> 0 | H20: 204 | I20: =H20*D20 -> 0 | J20: 230 | K20: =J20*D20 -> 0 | L20: =G20-'6'!D20 -> 0 | M20: =L20*J20 -> 0
A21: 250 ml PET | B21: Zero Coke | C21: 10 | D21: 30 | F21: =E21*H21 -> 0 | G21: =D21+E21 -> 30 | H21: 204 | I21: =H21*D21 -> 6120 | J21: 230 | K21: =J21*D21 -> 6900 | L21: =G21-'6'!D21 -> 1 | M21: =L21*J21 -> 230
A22: 250 ml PET | B22: Mazza | C22: 19 | D22: 77 | F22: =E22*H22 -> 0 | G22: =D22+E22 -> 77 | H22: 474.46 | I22: =H22*D22 -> 36533.42 | J22: 505 | K22: =J22*D22 -> 38885 | L22: =G22-'6'!D22 -> 26 | M22: =L22*J22 -> 13130
A23: 250 ml PET | B23: MM Pulpy orange | C23: 24 | D23: 67 | F23: =E23*H23 -> 0 | G23: =D23+E23 -> 67 | H23: 593.92 | I23: =H23*D23 -> 39792.64 | J23: 630 | K23: =J23*D23 -> 42210 | L23: =G23-'6'!D23 -> 18 | M23: =L23*J23 -> 11340
A24: 300 ml RGB | B24: Thums up | C24: 25 | D24: 63 | F24: =E24*H24 -> 0 | G24: =D24+E24 -> 63 | H24: 453.3 | I24: =H24*D24 -> 28557.9 | J24: 493 | K24: =J24*D24 -> 31059 | L24: =G24-'6'!D24 -> 0 | M24: =L24*J24 -> 0
A25: 300 ml RGB | B25: Sprite | C25: 25 | D25: 54 | F25: =E25*H25 -> 0 | G25: =D25+E25 -> 54 | H25: 453.3 | I25: =H25*D25 -> 24478.2 | J25: 493 | K25: =J25*D25 -> 26622 | L25: =G25-'6'!D25 -> 0 | M25: =L25*J25 -> 0
A26: 300 ml RGB | B26: Fanta | C26: 25 | F26: =E26*H26 -> 0 | G26: =D26+E26 -> 0 | H26: 453.3 | I26: =H26*D26 -> 0 | J26: 493 | K26: =J26*D26 -> 0 | L26: =G26-'6'!D26 -> 0 | M26: =L26*J26 -> 0
A27: 300 ml RGB | B27: Coke | C27: 25 | F27: =E27*H27 -> 0 | G27: =D27+E27 -> 0 | H27: 453.3 | I27: =H27*D27 -> 0 | J27: 493 | K27: =J27*D27 -> 0 | L27: =G27-'6'!D27 -> 0 | M27: =L27*J27 -> 0
A28: 300 ml CAN | B28: Thums up | C28: 40 | F28: =E28*H28 -> 0 | G28: =D28+E28 -> 0 | H28: 821.36 | I28: =H28*D28 -> 0 | J28: 878 | K28: =J28*D28 -> 0 | L28: =G28-'6'!D28 -> 0 | M28: =L28*J28 -> 0
A29: 300 ml CAN | B29: Sprite | C29: 40 | F29: =E29*H29 -> 0 | G29: =D29+E29 -> 0 | H29: 821.36 | I29: =H29*D29 -> 0 | J29: 878 | K29: =J29*D29 -> 0 | L29: =G29-'6'!D29 -> 0 | M29: =L29*J29 -> 0
A30: 300 ml CAN | B30: Limca | C30: 40 | F30: =E30*H30 -> 0 | G30: =D30+E30 -> 0 | H30: 817.58 | I30: =H30*D30 -> 0 | J30: 878 | K30: =J30*D30 -> 0 | L30: =G30-'6'!D30 -> 0 | M30: =L30*J30 -> 0
A31: 300 ml CAN | B31: Fanta | C31: 40 | F31: =E31*H31 -> 0 | G31: =D31+E31 -> 0 | H31: 817.58 | I31: =H31*D31 -> 0 | J31: 878 | K31: =J31*D31 -> 0 | L31: =G31-'6'!D31 -> 0 | M31: =L31*J31 -> 0
A32: 300 ml CAN | B32: Coke | C32: 40 | F32: =E32*H32 -> 0 | G32: =D32+E32 -> 0 | H32: 817.58 | I32: =H32*D32 -> 0 | J32: 878 | K32: =J32*D32 -> 0 | L32: =G32-'6'!D32 -> 0 | M32: =L32*J32 -> 0
A33: 300 ml CAN | B33: D'Coke | C33: 40 | F33: =E33*H33 -> 0 | G33: =D33+E33 -> 0 | H33: 817.58 | I33: =H33*D33 -> 0 | J33: 878 | K33: =J33*D33 -> 0 | L33: =G33-'6'!D33 -> 0 | M33: =L33*J33 -> 0
A34: 300 ml CAN | B34: Predator | C34: 60 | D34: 46 | F34: =E34*H34 -> 0 | G34: =D34+E34 -> 46 | H34: 1042.65 | I34: =H34*D34 -> 47961.9 | J34: 1110 | K34: =J34*D34 -> 51060 | L34: =G34-'6'!D34 -> 16 | M34: =L34*J34 -> 17760
A35: 300 ml | B35: Kinley Water | C35: 7 | D35: 15 | F35: =E35*H35 -> 0 | G35: =D35+E35 -> 15 | H35: 126.24 | I35: =H35*D35 -> 1893.6 | J35: 140 | K35: =J35*D35 -> 2100 | L35: =G35-'6'!D35 -> 0 | M35: =L35*J35 -> 0
A36: 350 ml CAN | B36: Monster | C36: 125 | D36: 21 | F36: =E36*H36 -> 0 | G36: =D36+E36 -> 21 | H36: 2050.54 | I36: =H36*D36 -> 43061.34 | J36: 2175 | K36: =J36*D36 -> 45675 | L36: =G36-'6'!D36 -> 5 | M36: =L36*J36 -> 10875
A37: 400 ml csd | B37: Thums up | C37: 20 | D37: 2 | F37: =E37*H37 -> 0 | G37: =D37+E37 -> 2 | H37: 399.19 | I37: =H37*D37 -> 798.38 | J37: 420 | K37: =J37*D37 -> 840 | L37: =G37-'6'!D37 -> 0 | M37: =L37*J37 -> 0
A38: 400 ml csd | B38: Sprite | C38: 20 | F38: =E38*H38 -> 0 | G38: =D38+E38 -> 0 | H38: 399.19 | I38: =H38*D38 -> 0 | J38: 420 | K38: =J38*D38 -> 0 | L38: =G38-'6'!D38 -> 0 | M38: =L38*J38 -> 0
A39: 400 ml csd | B39: Coke | C39: 20 | F39: =E39*H39 -> 0 | G39: =D39+E39 -> 0 | H39: 399.19 | I39: =H39*D39 -> 0 | J39: 420 | K39: =J39*D39 -> 0 | L39: =G39-'6'!D39 -> 0 | M39: =L39*J39 -> 0
A40: 500 ml | B40: Kinley Water | C40: 9 | D40: 73 | F40: =E40*H40 -> 0 | G40: =D40+E40 -> 73 | H40: 174.19 | I40: =H40*D40 -> 12715.87 | J40: 185 | K40: =J40*D40 -> 13505 | L40: =G40-'6'!D40 -> 0 | M40: =L40*J40 -> 0
...

Sheet 6
A1: Pack | B1: Flavour | C1: MRP | D1: Stock PC | E1: Recived pc | F1: Recived invoice | G1: Total PC | H1: Invoce cost | I1: Amount | J1: sale price | K1: Amount | L1: SALE Pc | M1: SALE Amount
A2: 150 ml Tetra | B2: Mazza | C2: 9 | D2: 481 | F2: =E2*H2 -> 0 | G2: =D2+E2 -> 481 | H2: 308.13 | I2: =H2*D2 -> 148210.53 | J2: 326 | K2: =J2*D2 -> 156806 | L2: =G2-'7'!D2 -> 17 | M2: =L2*J2 -> 5542
A3: 150 ml Tetra | B3: MM Apple | C3: 9 | D3: 66 | F3: =E3*H3 -> 0 | G3: =D3+E3 -> 66 | H3: 308.19 | I3: =H3*D3 -> 20340.54 | J3: 326 | K3: =J3*D3 -> 21516 | L3: =G3-'7'!D3 -> 4 | M3: =L3*J3 -> 1304
A4: 150 ml Tetra | B4: MM LMN Fresh | C4: 9 | F4: =E4*H4 -> 0 | G4: =D4+E4 -> 0 | H4: 308.19 | I4: =H4*D4 -> 0 | J4: 326 | K4: =J4*D4 -> 0 | L4: =G4-'7'!D4 -> 0 | M4: =L4*J4 -> 0
A5: 200 ml RGB | B5: Thums up | C5: 10 | D5: 184 | F5: =E5*H5 -> 0 | G5: =D5+E5 -> 184 | H5: 174.77 | I5: =H5*D5 -> 32157.68 | J5: 192 | K5: =J5*D5 -> 35328 | L5: =G5-'7'!D5 -> 19 | M5: =L5*J5 -> 3648
A6: 200 ml RGB | B6: Sprite | C6: 10 | D6: 192 | F6: =E6*H6 -> 0 | G6: =D6+E6 -> 192 | H6: 174.77 | I6: =H6*D6 -> 33555.84 | J6: 192 | K6: =J6*D6 -> 36864 | L6: =G6-'7'!D6 -> 12 | M6: =L6*J6 -> 2304
A7: 200 ml RGB | B7: Limca | C7: 10 | D7: 52 | F7: =E7*H7 -> 0 | G7: =D7+E7 -> 52 | H7: 174.77 | I7: =H7*D7 -> 9088.04 | J7: 192 | K7: =J7*D7 -> 9984 | L7: =G7-'7'!D7 -> 4 | M7: =L7*J7 -> 768
A8: 200 ml RGB | B8: Fanta | C8: 10 | D8: 83 | F8: =E8*H8 -> 0 | G8: =D8+E8 -> 83 | H8: 174.77 | I8: =H8*D8 -> 14505.91 | J8: 192 | K8: =J8*D8 -> 15936 | L8: =G8-'7'!D8 -> 10 | M8: =L8*J8 -> 1920
A9: 200 ml RGB | B9: Coke | C9: 10 | D9: 180 | F9: =E9*H9 -> 0 | G9: =D9+E9 -> 180 | H9: 174.77 | I9: =H9*D9 -> 31458.6 | J9: 192 | K9: =J9*D9 -> 34560 | L9: =G9-'7'!D9 -> 11 | M9: =L9*J9 -> 2112
A10: 200 ml RGB | B10: Mazza | C10: 14 | F10: =E10*H10 -> 0 | G10: =D10+E10 -> 0 | H10: 259.54 | I10: =H10*D10 -> 0 | J10: 282 | K10: =J10*D10 -> 0 | L10: =G10-'7'!D10 -> 0 | M10: =L10*J10 -> 0
A11: 250 ml PET | B11: Thums up Charge | C11: 20 | D11: 37 | F11: =E11*H11 -> 0 | G11: =D11+E11 -> 37 | H11: 470.8 | I11: =H11*D11 -> 17419.6 | J11: 505 | K11: =J11*D11 -> 18685 | L11: =G11-'7'!D11 -> 2 | M11: =L11*J11 -> 1010
A12: 250 ml PET | B12: Thums up | C12: 20 | D12: 413 | F12: =E12*H12 -> 0 | G12: =D12+E12 -> 413 | H12: 475.77 | I12: =H12*D12 -> 196493.01 | J12: 505 | K12: =J12*D12 -> 208565 | L12: =G12-'7'!D12 -> 56 | M12: =L12*J12 -> 28280
A13: 250 ml PET | B13: Sprite | C13: 20 | D13: 278 | F13: =E13*H13 -> 0 | G13: =D13+E13 -> 278 | H13: 475.77 | I13: =H13*D13 -> 132264.06 | J13: 505 | K13: =J13*D13 -> 140390 | L13: =G13-'7'!D13 -> 26 | M13: =L13*J13 -> 13130
A14: 250 ml PET | B14: Limca | C14: 20 | D14: 46 | F14: =E14*H14 -> 0 | G14: =D14+E14 -> 46 | H14: 470.8 | I14: =H14*D14 -> 21656.8 | J14: 505 | K14: =J14*D14 -> 23230 | L14: =G14-'7'!D14 -> 7 | M14: =L14*J14 -> 3535
A15: 250 ml PET | B15: Fanta | C15: 20 | D15: 47 | F15: =E15*H15 -> 0 | G15: =D15+E15 -> 47 | H15: 470.8 | I15: =H15*D15 -> 22127.6 | J15: 505 | K15: =J15*D15 -> 23735 | L15: =G15-'7'!D15 -> 4 | M15: =L15*J15 -> 2020
A16: 250 ml PET | B16: Coke | C16: 20 | F16: =E16*H16 -> 0 | G16: =D16+E16 -> 0 | H16: 470.8 | I16: =H16*D16 -> 0 | J16: 505 | K16: =J16*D16 -> 0 | L16: =G16-'7'!D16 -> 0 | M16: =L16*J16 -> 0
A17: 250 ml PET | B17: Kinley Soda | C17: 11 | D17: 80 | F17: =E17*H17 -> 0 | G17: =D17+E17 -> 80 | H17: 235.59 | I17: =H17*D17 -> 18847.2 | J17: 250 | K17: =J17*D17 -> 20000 | L17: =G17-'7'!D17 -> 4 | M17: =L17*J17 -> 1000
A18: 250 ml PET | B18: RimZim Fiz | C18: 20 | F18: =E18*H18 -> 0 | G18: =D18+E18 -> 0 | H18: 470.8 | I18: =H18*D18 -> 0 | J18: 500 | K18: =J18*D18 -> 0 | L18: =G18-'7'!D18 -> 0 | M18: =L18*J18 -> 0
A19: 250 ml PET | B19: Zero Thums up | C19: 10 | F19: =E19*H19 -> 0 | G19: =D19+E19 -> 0 | H19: 204 | I19: =H19*D19 -> 0 | J19: 230 | K19: =J19*D19 -> 0 | L19: =G19-'7'!D19 -> 0 | M19: =L19*J19 -> 0
A20: 250 ml PET | B20: Zero Sprite | C20: 10 | F20: =E20*H20 -> 0 | G20: =D20+E20 -> 0 | H20: 204 | I20: =H20*D20 -> 0 | J20: 230 | K20: =J20*D20 -> 0 | L20: =G20-'7'!D20 -> 0 | M20: =L20*J20 -> 0
A21: 250 ml PET | B21: Zero Coke | C21: 10 | D21: 29 | F21: =E21*H21 -> 0 | G21: =D21+E21 -> 29 | H21: 204 | I21: =H21*D21 -> 5916 | J21: 230 | K21: =J21*D21 -> 6670 | L21: =G21-'7'!D21 -> 1 | M21: =L21*J21 -> 230
A22: 250 ml PET | B22: Mazza | C22: 19 | D22: 51 | F22: =E22*H22 -> 0 | G22: =D22+E22 -> 51 | H22: 474.46 | I22: =H22*D22 -> 24197.46 | J22: 505 | K22: =J22*D22 -> 25755 | L22: =G22-'7'!D22 -> 21 | M22: =L22*J22 -> 10605
A23: 250 ml PET | B23: MM Pulpy orange | C23: 24 | D23: 49 | F23: =E23*H23 -> 0 | G23: =D23+E23 -> 49 | H23: 593.92 | I23: =H23*D23 -> 29102.08 | J23: 630 | K23: =J23*D23 -> 30870 | L23: =G23-'7'!D23 -> 14 | M23: =L23*J23 -> 8820
A24: 300 ml RGB | B24: Thums up | C24: 25 | D24: 63 | F24: =E24*H24 -> 0 | G24: =D24+E24 -> 63 | H24: 453.3 | I24: =H24*D24 -> 28557.9 | J24: 493 | K24: =J24*D24 -> 31059 | L24: =G24-'7'!D24 -> 0 | M24: =L24*J24 -> 0
A25: 300 ml RGB | B25: Sprite | C25: 25 | D25: 54 | F25: =E25*H25 -> 0 | G25: =D25+E25 -> 54 | H25: 453.3 | I25: =H25*D25 -> 24478.2 | J25: 493 | K25: =J25*D25 -> 26622 | L25: =G25-'7'!D25 -> 0 | M25: =L25*J25 -> 0
A26: 300 ml RGB | B26: Fanta | C26: 25 | F26: =E26*H26 -> 0 | G26: =D26+E26 -> 0 | H26: 453.3 | I26: =H26*D26 -> 0 | J26: 493 | K26: =J26*D26 -> 0 | L26: =G26-'7'!D26 -> 0 | M26: =L26*J26 -> 0
A27: 300 ml RGB | B27: Coke | C27: 25 | F27: =E27*H27 -> 0 | G27: =D27+E27 -> 0 | H27: 453.3 | I27: =H27*D27 -> 0 | J27: 493 | K27: =J27*D27 -> 0 | L27: =G27-'7'!D27 -> 0 | M27: =L27*J27 -> 0
A28: 300 ml CAN | B28: Thums up | C28: 40 | F28: =E28*H28 -> 0 | G28: =D28+E28 -> 0 | H28: 821.36 | I28: =H28*D28 -> 0 | J28: 878 | K28: =J28*D28 -> 0 | L28: =G28-'7'!D28 -> 0 | M28: =L28*J28 -> 0
A29: 300 ml CAN | B29: Sprite | C29: 40 | F29: =E29*H29 -> 0 | G29: =D29+E29 -> 0 | H29: 821.36 | I29: =H29*D29 -> 0 | J29: 878 | K29: =J29*D29 -> 0 | L29: =G29-'7'!D29 -> 0 | M29: =L29*J29 -> 0
A30: 300 ml CAN | B30: Limca | C30: 40 | F30: =E30*H30 -> 0 | G30: =D30+E30 -> 0 | H30: 817.58 | I30: =H30*D30 -> 0 | J30: 878 | K30: =J30*D30 -> 0 | L30: =G30-'7'!D30 -> 0 | M30: =L30*J30 -> 0
A31: 300 ml CAN | B31: Fanta | C31: 40 | F31: =E31*H31 -> 0 | G31: =D31+E31 -> 0 | H31: 817.58 | I31: =H31*D31 -> 0 | J31: 878 | K31: =J31*D31 -> 0 | L31: =G31-'7'!D31 -> 0 | M31: =L31*J31 -> 0
A32: 300 ml CAN | B32: Coke | C32: 40 | F32: =E32*H32 -> 0 | G32: =D32+E32 -> 0 | H32: 817.58 | I32: =H32*D32 -> 0 | J32: 878 | K32: =J32*D32 -> 0 | L32: =G32-'7'!D32 -> 0 | M32: =L32*J32 -> 0
A33: 300 ml CAN | B33: D'Coke | C33: 40 | F33: =E33*H33 -> 0 | G33: =D33+E33 -> 0 | H33: 817.58 | I33: =H33*D33 -> 0 | J33: 878 | K33: =J33*D33 -> 0 | L33: =G33-'7'!D33 -> 0 | M33: =L33*J33 -> 0
A34: 300 ml CAN | B34: Predator | C34: 60 | D34: 30 | F34: =E34*H34 -> 0 | G34: =D34+E34 -> 30 | H34: 1042.65 | I34: =H34*D34 -> 31279.5 | J34: 1110 | K34: =J34*D34 -> 33300 | L34: =G34-'7'!D34 -> 13 | M34: =L34*J34 -> 14430
A35: 300 ml | B35: Kinley Water | C35: 7 | D35: 15 | F35: =E35*H35 -> 0 | G35: =D35+E35 -> 15 | H35: 126.24 | I35: =H35*D35 -> 1893.6 | J35: 140 | K35: =J35*D35 -> 2100 | L35: =G35-'7'!D35 -> 4 | M35: =L35*J35 -> 560
A36: 350 ml CAN | B36: Monster | C36: 125 | D36: 16 | F36: =E36*H36 -> 0 | G36: =D36+E36 -> 16 | H36: 2050.54 | I36: =H36*D36 -> 32808.64 | J36: 2175 | K36: =J36*D36 -> 34800 | L36: =G36-'7'!D36 -> 4 | M36: =L36*J36 -> 8700
A37: 400 ml csd | B37: Thums up | C37: 20 | D37: 2 | F37: =E37*H37 -> 0 | G37: =D37+E37 -> 2 | H37: 399.19 | I37: =H37*D37 -> 798.38 | J37: 420 | K37: =J37*D37 -> 840 | L37: =G37-'7'!D37 -> 0 | M37: =L37*J37 -> 0
A38: 400 ml csd | B38: Sprite | C38: 20 | F38: =E38*H38 -> 0 | G38: =D38+E38 -> 0 | H38: 399.19 | I38: =H38*D38 -> 0 | J38: 420 | K38: =J38*D38 -> 0 | L38: =G38-'7'!D38 -> 0 | M38: =L38*J38 -> 0
A39: 400 ml csd | B39: Coke | C39: 20 | F39: =E39*H39 -> 0 | G39: =D39+E39 -> 0 | H39: 399.19 | I39: =H39*D39 -> 0 | J39: 420 | K39: =J39*D39 -> 0 | L39: =G39-'7'!D39 -> 0 | M39: =L39*J39 -> 0
A40: 500 ml | B40: Kinley Water | C40: 9 | D40: 73 | F40: =E40*H40 -> 0 | G40: =D40+E40 -> 73 | H40: 174.19 | I40: =H40*D40 -> 12715.87 | J40: 185 | K40: =J40*D40 -> 13505 | L40: =G40-'7'!D40 -> 0 | M40: =L40*J40 -> 0
...

Sheet 7
A1: Pack | B1: Flavour | C1: MRP | D1: Stock PC | E1: Recived pc | F1: Recived invoice | G1: Total PC | H1: Invoce cost | I1: Amount | J1: sale price | K1: Amount | L1: SALE Pc | M1: SALE Amount
A2: 150 ml Tetra | B2: Mazza | C2: 9 | D2: 464 | F2: =E2*H2 -> 0 | G2: =D2+E2 -> 464 | H2: 308.13 | I2: =H2*D2 -> 142972.32 | J2: 326 | K2: =J2*D2 -> 151264 | L2: =G2-'8'!D2 -> 16 | M2: =L2*J2 -> 5216
A3: 150 ml Tetra | B3: MM Apple | C3: 9 | D3: 62 | E3: 42 | F3: =E3*H3 -> 12943.98 | G3: =D3+E3 -> 104 | H3: 308.19 | I3: =H3*D3 -> 19107.78 | J3: 326 | K3: =J3*D3 -> 20212 | L3: =G3-'8'!D3 -> 2 | M3: =L3*J3 -> 652
A4: 150 ml Tetra | B4: MM LMN Fresh | C4: 9 | F4: =E4*H4 -> 0 | G4: =D4+E4 -> 0 | H4: 308.19 | I4: =H4*D4 -> 0 | J4: 326 | K4: =J4*D4 -> 0 | L4: =G4-'8'!D4 -> 0 | M4: =L4*J4 -> 0
A5: 200 ml RGB | B5: Thums up | C5: 10 | D5: 165 | E5: 144 | F5: =E5*H5 -> 25166.88 | G5: =D5+E5 -> 309 | H5: 174.77 | I5: =H5*D5 -> 28837.05 | J5: 192 | K5: =J5*D5 -> 31680 | L5: =G5-'8'!D5 -> 19 | M5: =L5*J5 -> 3648
A6: 200 ml RGB | B6: Sprite | C6: 10 | D6: 180 | E6: 72 | F6: =E6*H6 -> 12583.44 | G6: =D6+E6 -> 252 | H6: 174.77 | I6: =H6*D6 -> 31458.6 | J6: 192 | K6: =J6*D6 -> 34560 | L6: =G6-'8'!D6 -> 11 | M6: =L6*J6 -> 2112
A7: 200 ml RGB | B7: Limca | C7: 10 | D7: 48 | F7: =E7*H7 -> 0 | G7: =D7+E7 -> 48 | H7: 174.77 | I7: =H7*D7 -> 8388.96 | J7: 192 | K7: =J7*D7 -> 9216 | L7: =G7-'8'!D7 -> 1 | M7: =L7*J7 -> 192
A8: 200 ml RGB | B8: Fanta | C8: 10 | D8: 73 | F8: =E8*H8 -> 0 | G8: =D8+E8 -> 73 | H8: 174.77 | I8: =H8*D8 -> 12758.21 | J8: 192 | K8: =J8*D8 -> 14016 | L8: =G8-'8'!D8 -> 10 | M8: =L8*J8 -> 1920
A9: 200 ml RGB | B9: Coke | C9: 10 | D9: 169 | F9: =E9*H9 -> 0 | G9: =D9+E9 -> 169 | H9: 174.77 | I9: =H9*D9 -> 29536.13 | J9: 192 | K9: =J9*D9 -> 32448 | L9: =G9-'8'!D9 -> 7 | M9: =L9*J9 -> 1344
A10: 200 ml RGB | B10: Mazza | C10: 14 | F10: =E10*H10 -> 0 | G10: =D10+E10 -> 0 | H10: 259.54 | I10: =H10*D10 -> 0 | J10: 282 | K10: =J10*D10 -> 0 | L10: =G10-'8'!D10 -> 0 | M10: =L10*J10 -> 0
A11: 250 ml PET | B11: Thums up Charge | C11: 20 | D11: 35 | F11: =E11*H11 -> 0 | G11: =D11+E11 -> 35 | H11: 470.8 | I11: =H11*D11 -> 16478 | J11: 505 | K11: =J11*D11 -> 17675 | L11: =G11-'8'!D11 -> 5 | M11: =L11*J11 -> 2525
A12: 250 ml PET | B12: Thums up | C12: 20 | D12: 357 | F12: =E12*H12 -> 0 | G12: =D12+E12 -> 357 | H12: 475.77 | I12: =H12*D12 -> 169849.89 | J12: 505 | K12: =J12*D12 -> 180285 | L12: =G12-'8'!D12 -> 92 | M12: =L12*J12 -> 46460
A13: 250 ml PET | B13: Sprite | C13: 20 | D13: 252 | F13: =E13*H13 -> 0 | G13: =D13+E13 -> 252 | H13: 475.77 | I13: =H13*D13 -> 119894.04 | J13: 505 | K13: =J13*D13 -> 127260 | L13: =G13-'8'!D13 -> 40 | M13: =L13*J13 -> 20200
A14: 250 ml PET | B14: Limca | C14: 20 | D14: 39 | F14: =E14*H14 -> 0 | G14: =D14+E14 -> 39 | H14: 470.8 | I14: =H14*D14 -> 18361.2 | J14: 505 | K14: =J14*D14 -> 19695 | L14: =G14-'8'!D14 -> 7 | M14: =L14*J14 -> 3535
A15: 250 ml PET | B15: Fanta | C15: 20 | D15: 43 | F15: =E15*H15 -> 0 | G15: =D15+E15 -> 43 | H15: 470.8 | I15: =H15*D15 -> 20244.4 | J15: 505 | K15: =J15*D15 -> 21715 | L15: =G15-'8'!D15 -> 3 | M15: =L15*J15 -> 1515
A16: 250 ml PET | B16: Coke | C16: 20 | F16: =E16*H16 -> 0 | G16: =D16+E16 -> 0 | H16: 470.8 | I16: =H16*D16 -> 0 | J16: 505 | K16: =J16*D16 -> 0 | L16: =G16-'8'!D16 -> 0 | M16: =L16*J16 -> 0
A17: 250 ml PET | B17: Kinley Soda | C17: 11 | D17: 76 | F17: =E17*H17 -> 0 | G17: =D17+E17 -> 76 | H17: 235.59 | I17: =H17*D17 -> 17904.84 | J17: 250 | K17: =J17*D17 -> 19000 | L17: =G17-'8'!D17 -> 3 | M17: =L17*J17 -> 750
A18: 250 ml PET | B18: RimZim Fiz | C18: 20 | F18: =E18*H18 -> 0 | G18: =D18+E18 -> 0 | H18: 470.8 | I18: =H18*D18 -> 0 | J18: 500 | K18: =J18*D18 -> 0 | L18: =G18-'8'!D18 -> 0 | M18: =L18*J18 -> 0
A19: 250 ml PET | B19: Zero Thums up | C19: 10 | F19: =E19*H19 -> 0 | G19: =D19+E19 -> 0 | H19: 204 | I19: =H19*D19 -> 0 | J19: 230 | K19: =J19*D19 -> 0 | L19: =G19-'8'!D19 -> 0 | M19: =L19*J19 -> 0
A20: 250 ml PET | B20: Zero Sprite | C20: 10 | F20: =E20*H20 -> 0 | G20: =D20+E20 -> 0 | H20: 204 | I20: =H20*D20 -> 0 | J20: 230 | K20: =J20*D20 -> 0 | L20: =G20-'8'!D20 -> 0 | M20: =L20*J20 -> 0
A21: 250 ml PET | B21: Zero Coke | C21: 10 | D21: 28 | F21: =E21*H21 -> 0 | G21: =D21+E21 -> 28 | H21: 204 | I21: =H21*D21 -> 5712 | J21: 230 | K21: =J21*D21 -> 6440 | L21: =G21-'8'!D21 -> 0 | M21: =L21*J21 -> 0
A22: 250 ml PET | B22: Mazza | C22: 19 | D22: 30 | F22: =E22*H22 -> 0 | G22: =D22+E22 -> 30 | H22: 474.46 | I22: =H22*D22 -> 14233.8 | J22: 505 | K22: =J22*D22 -> 15150 | L22: =G22-'8'!D22 -> 22 | M22: =L22*J22 -> 11110
A23: 250 ml PET | B23: MM Pulpy orange | C23: 24 | D23: 35 | E23: =108+36 -> 144 | F23: =E23*H23 -> 85524.48 | G23: =D23+E23 -> 179 | H23: 593.92 | I23: =H23*D23 -> 20787.2 | J23: 630 | K23: =J23*D23 -> 22050 | L23: =G23-'8'!D23 -> 14 | M23: =L23*J23 -> 8820
A24: 300 ml RGB | B24: Thums up | C24: 25 | D24: 63 | E24: 108 | F24: =E24*H24 -> 48956.4 | G24: =D24+E24 -> 171 | H24: 453.3 | I24: =H24*D24 -> 28557.9 | J24: 493 | K24: =J24*D24 -> 31059 | L24: =G24-'8'!D24 -> 0 | M24: =L24*J24 -> 0
A25: 300 ml RGB | B25: Sprite | C25: 25 | D25: 54 | F25: =E25*H25 -> 0 | G25: =D25+E25 -> 54 | H25: 453.3 | I25: =H25*D25 -> 24478.2 | J25: 493 | K25: =J25*D25 -> 26622 | L25: =G25-'8'!D25 -> 0 | M25: =L25*J25 -> 0
A26: 300 ml RGB | B26: Fanta | C26: 25 | F26: =E26*H26 -> 0 | G26: =D26+E26 -> 0 | H26: 453.3 | I26: =H26*D26 -> 0 | J26: 493 | K26: =J26*D26 -> 0 | L26: =G26-'8'!D26 -> 0 | M26: =L26*J26 -> 0
A27: 300 ml RGB | B27: Coke | C27: 25 | F27: =E27*H27 -> 0 | G27: =D27+E27 -> 0 | H27: 453.3 | I27: =H27*D27 -> 0 | J27: 493 | K27: =J27*D27 -> 0 | L27: =G27-'8'!D27 -> 0 | M27: =L27*J27 -> 0
A28: 300 ml CAN | B28: Thums up | C28: 40 | F28: =E28*H28 -> 0 | G28: =D28+E28 -> 0 | H28: 821.36 | I28: =H28*D28 -> 0 | J28: 878 | K28: =J28*D28 -> 0 | L28: =G28-'8'!D28 -> 0 | M28: =L28*J28 -> 0
A29: 300 ml CAN | B29: Sprite | C29: 40 | F29: =E29*H29 -> 0 | G29: =D29+E29 -> 0 | H29: 821.36 | I29: =H29*D29 -> 0 | J29: 878 | K29: =J29*D29 -> 0 | L29: =G29-'8'!D29 -> 0 | M29: =L29*J29 -> 0
A30: 300 ml CAN | B30: Limca | C30: 40 | F30: =E30*H30 -> 0 | G30: =D30+E30 -> 0 | H30: 817.58 | I30: =H30*D30 -> 0 | J30: 878 | K30: =J30*D30 -> 0 | L30: =G30-'8'!D30 -> 0 | M30: =L30*J30 -> 0
A31: 300 ml CAN | B31: Fanta | C31: 40 | F31: =E31*H31 -> 0 | G31: =D31+E31 -> 0 | H31: 817.58 | I31: =H31*D31 -> 0 | J31: 878 | K31: =J31*D31 -> 0 | L31: =G31-'8'!D31 -> 0 | M31: =L31*J31 -> 0
A32: 300 ml CAN | B32: Coke | C32: 40 | F32: =E32*H32 -> 0 | G32: =D32+E32 -> 0 | H32: 817.58 | I32: =H32*D32 -> 0 | J32: 878 | K32: =J32*D32 -> 0 | L32: =G32-'8'!D32 -> 0 | M32: =L32*J32 -> 0
A33: 300 ml CAN | B33: D'Coke | C33: 40 | F33: =E33*H33 -> 0 | G33: =D33+E33 -> 0 | H33: 817.58 | I33: =H33*D33 -> 0 | J33: 878 | K33: =J33*D33 -> 0 | L33: =G33-'8'!D33 -> 0 | M33: =L33*J33 -> 0
A34: 300 ml CAN | B34: Predator | C34: 60 | D34: 17 | F34: =E34*H34 -> 0 | G34: =D34+E34 -> 17 | H34: 1042.65 | I34: =H34*D34 -> 17725.05 | J34: 1110 | K34: =J34*D34 -> 18870 | L34: =G34-'8'!D34 -> 13 | M34: =L34*J34 -> 14430
A35: 300 ml | B35: Kinley Water | C35: 7 | D35: 11 | F35: =E35*H35 -> 0 | G35: =D35+E35 -> 11 | H35: 126.24 | I35: =H35*D35 -> 1388.64 | J35: 140 | K35: =J35*D35 -> 1540 | L35: =G35-'8'!D35 -> 0 | M35: =L35*J35 -> 0
A36: 350 ml CAN | B36: Monster | C36: 125 | D36: 12 | F36: =E36*H36 -> 0 | G36: =D36+E36 -> 12 | H36: 2050.54 | I36: =H36*D36 -> 24606.48 | J36: 2175 | K36: =J36*D36 -> 26100 | L36: =G36-'8'!D36 -> 1 | M36: =L36*J36 -> 2175
A37: 400 ml csd | B37: Thums up | C37: 20 | D37: 2 | F37: =E37*H37 -> 0 | G37: =D37+E37 -> 2 | H37: 399.19 | I37: =H37*D37 -> 798.38 | J37: 420 | K37: =J37*D37 -> 840 | L37: =G37-'8'!D37 -> 0 | M37: =L37*J37 -> 0
A38: 400 ml csd | B38: Sprite | C38: 20 | F38: =E38*H38 -> 0 | G38: =D38+E38 -> 0 | H38: 399.19 | I38: =H38*D38 -> 0 | J38: 420 | K38: =J38*D38 -> 0 | L38: =G38-'8'!D38 -> 0 | M38: =L38*J38 -> 0
A39: 400 ml csd | B39: Coke | C39: 20 | F39: =E39*H39 -> 0 | G39: =D39+E39 -> 0 | H39: 399.19 | I39: =H39*D39 -> 0 | J39: 420 | K39: =J39*D39 -> 0 | L39: =G39-'8'!D39 -> 0 | M39: =L39*J39 -> 0
A40: 500 ml | B40: Kinley Water | C40: 9 | D40: 73 | F40: =E40*H40 -> 0 | G40: =D40+E40 -> 73 | H40: 174.19 | I40: =H40*D40 -> 12715.87 | J40: 185 | K40: =J40*D40 -> 13505 | L40: =G40-'8'!D40 -> 0 | M40: =L40*J40 -> 0
...

Sheet 8
A1: Pack | B1: Flavour | C1: MRP | D1: Stock PC | E1: Recived pc | F1: Recived invoice | G1: Total PC | H1: Invoce cost | I1: Amount | J1: sale price | K1: Amount | L1: SALE Pc | M1: SALE Amount
A2: 150 ml Tetra | B2: Mazza | C2: 9 | D2: 448 | F2: =E2*H2 -> 0 | G2: =D2+E2 -> 448 | H2: 308.13 | I2: =H2*D2 -> 138042.24 | J2: 326 | K2: =J2*D2 -> 146048 | L2: =G2-'9'!D2 -> 14 | M2: =L2*J2 -> 4564
A3: 150 ml Tetra | B3: MM Apple | C3: 9 | D3: 102 | F3: =E3*H3 -> 0 | G3: =D3+E3 -> 102 | H3: 308.19 | I3: =H3*D3 -> 31435.38 | J3: 326 | K3: =J3*D3 -> 33252 | L3: =G3-'9'!D3 -> 3 | M3: =L3*J3 -> 978
A4: 150 ml Tetra | B4: MM LMN Fresh | C4: 9 | F4: =E4*H4 -> 0 | G4: =D4+E4 -> 0 | H4: 308.19 | I4: =H4*D4 -> 0 | J4: 326 | K4: =J4*D4 -> 0 | L4: =G4-'9'!D4 -> 0 | M4: =L4*J4 -> 0
A5: 200 ml RGB | B5: Thums up | C5: 10 | D5: 290 | F5: =E5*H5 -> 0 | G5: =D5+E5 -> 290 | H5: 174.77 | I5: =H5*D5 -> 50683.3 | J5: 192 | K5: =J5*D5 -> 55680 | L5: =G5-'9'!D5 -> 19 | M5: =L5*J5 -> 3648
A6: 200 ml RGB | B6: Sprite | C6: 10 | D6: 241 | F6: =E6*H6 -> 0 | G6: =D6+E6 -> 241 | H6: 174.77 | I6: =H6*D6 -> 42119.57 | J6: 192 | K6: =J6*D6 -> 46272 | L6: =G6-'9'!D6 -> 14 | M6: =L6*J6 -> 2688
A7: 200 ml RGB | B7: Limca | C7: 10 | D7: 47 | F7: =E7*H7 -> 0 | G7: =D7+E7 -> 47 | H7: 174.77 | I7: =H7*D7 -> 8214.19 | J7: 192 | K7: =J7*D7 -> 9024 | L7: =G7-'9'!D7 -> 3 | M7: =L7*J7 -> 576
A8: 200 ml RGB | B8: Fanta | C8: 10 | D8: 63 | F8: =E8*H8 -> 0 | G8: =D8+E8 -> 63 | H8: 174.77 | I8: =H8*D8 -> 11010.51 | J8: 192 | K8: =J8*D8 -> 12096 | L8: =G8-'9'!D8 -> 11 | M8: =L8*J8 -> 2112
A9: 200 ml RGB | B9: Coke | C9: 10 | D9: 162 | F9: =E9*H9 -> 0 | G9: =D9+E9 -> 162 | H9: 174.77 | I9: =H9*D9 -> 28312.74 | J9: 192 | K9: =J9*D9 -> 31104 | L9: =G9-'9'!D9 -> 6 | M9: =L9*J9 -> 1152
A10: 200 ml RGB | B10: Mazza | C10: 14 | F10: =E10*H10 -> 0 | G10: =D10+E10 -> 0 | H10: 259.54 | I10: =H10*D10 -> 0 | J10: 282 | K10: =J10*D10 -> 0 | L10: =G10-'9'!D10 -> 0 | M10: =L10*J10 -> 0
A11: 250 ml PET | B11: Thums up Charge | C11: 20 | D11: 30 | F11: =E11*H11 -> 0 | G11: =D11+E11 -> 30 | H11: 470.8 | I11: =H11*D11 -> 14124 | J11: 505 | K11: =J11*D11 -> 15150 | L11: =G11-'9'!D11 -> 2 | M11: =L11*J11 -> 1010
A12: 250 ml PET | B12: Thums up | C12: 20 | D12: 265 | F12: =E12*H12 -> 0 | G12: =D12+E12 -> 265 | H12: 475.77 | I12: =H12*D12 -> 126079.05 | J12: 505 | K12: =J12*D12 -> 133825 | L12: =G12-'9'!D12 -> 77 | M12: =L12*J12 -> 38885
A13: 250 ml PET | B13: Sprite | C13: 20 | D13: 212 | F13: =E13*H13 -> 0 | G13: =D13+E13 -> 212 | H13: 475.77 | I13: =H13*D13 -> 100863.24 | J13: 505 | K13: =J13*D13 -> 107060 | L13: =G13-'9'!D13 -> 37 | M13: =L13*J13 -> 18685
